Workbook

Sheet Cover
A1: INTERNATIONAL TRADE PARK HOUSTON
A2: Capital Model | PLUSAdvantage™ 2026 — CONFIDENTIAL
A4: PROJECT SNAPSHOT
A6: Total Acres | C6: Net Lot SF | E6: Total Lots | G6: Gross Lot Value
A7: 136 | C7: 4,337,705 | E7: 30 | G7: $39,390,437
A9: Total Revenue | C9: Total Project Cost | E9: Total Profit | G9: Project IRR
A10: $61,214,819 | C10: $38,058,952 | E10: $23,155,868 | G10: 63.6%
A12: Project Multiple | C12: Equity IRR | E12: Equity Multiple | G12: Peak Loan Balance
A13: 3.03x | C13: 39.3% | E13: 2.11x | G13: $671,535
A18: TAB DIRECTORY
A19: 📋 User Instructions | B19: Model guide, Copilot activation, color legend, 60-prompt library ← START HERE
A20: Cover | B20: Project KPI dashboard, snapshot tiles, navigation index
A21: Assumptions | B21: ALL inputs — lot pricing, timeline, costs, MUD bonds, equity terms
A22: Total Budget | B22: Full project budget: Land + Horizontal + Soft + Vertical + Financing
A23: Land | B23: Parcel breakdown, acres by use, lot value analysis, absorption
A24: Improvements | B24: Horizontal infrastructure detail, unit costs, phasing schedule
A25: Sources & Uses | B25: Capital balancing: all uses vs all sources, coverage ratios
A26: Monthly Cash Flow | B26: 50-month draw schedule, MUD receipts, lot proceeds, loan balance
A27: Dev Budget | B27: Uses of Funds summary with % of total and $/SF columns
A28: Capital Stack | B28: MUD bonds, construction loan, equity tranche, underwriting tests
A29: Pro Forma | B29: Revenue summary, cost summary, lot sales by type, absorption
A30: JV Waterfall | B30: 4-step distribution: capital return → preferred → 50/50 split
... A37: Title | B37: Navy fill / gold text — title bar

Sheet Assumptions
A1: INTERNATIONAL TRADE PARK HOUSTON — ASSUMPTIONS
A2: All highlighted cells are user-changeable inputs
A4: PROPERTY INFORMATION
A5: Project Name | B5: International Trade Park Houston
A6: Location | B6: Houston, Texas
A7: Total Gross Acres | B7: 136
A8: Net Lot Acres | B8: 99.58
A9: Net Lot SF | B9: 4337705
A10: Total Lots | B10: 30
A12: LOT MIX & PRICING
A13: Lot Type | B13: # Lots | C13: Acres | D13: Price/SF | E13: Gross Value | F13: % of Total
A14: Industrial (27.6 ac avg) | B14: 8 | C14: 27.6 | D14: 7.653 | E14: 9190000 | F14: =E14/$E$17 -> 0.23330536
A15: Retail (1-acre lots) | B15: 18 | C15: 23.5 | D15: 14.556 | E15: 14900000 | F15: =E15/$E$17 -> 0.3782644
A16: Multifamily | B16: 4 | C16: 48.5 | D16: 7.242 | E16: 15300437 | F16: =E16/$E$17 -> 0.38843024
A17: TOTAL LOT VALUE | B17: =SUM(B14:B16) -> 30 | C17: =SUM(C14:C16) -> 99.6 | E17: =SUM(E14:E16) -> 39390437 | F17: =1 -> 1
A19: PROJECT TIMELINE
A20: Project Start Date | B20: February 2026
A21: Project End Date | B21: April 2030
A22: Project Duration (Months) | B22: 50
A23: Sales Start (Month #) | B23: 5
A24: Sales End (Month #) | B24: 22
A25: MUD Bond 1st Issuance (Month #) | B25: 15
A26: MUD Bond 2nd Issuance (Month #) | B26: 21
A28: HARD COSTS
A29: Water System | B29: 1993000 | C29: =B29/B35 -> 0.084489607
A30: Sanitary Sewer | B30: 3432000 | C30: =B30/B35 -> 0.14549339
A31: Storm Sewer | B31: 12527000 | C31: =B31/B35 -> 0.53105936
A32: Roadway | B32: 5098000 | C32: =B32/B35 -> 0.21612043
A33: Erosion Control | B33: 262000 | C33: =B33/B35 -> 0.011107013
A34: Contingency (Hard) | B34: 276700 | C34: =B34/B35 -> 0.011730193
A35: Total Hard Costs | B35: =SUM(B29:B34) -> 23588700
A37: SOFT COSTS
A38: Testing / Inspection | B38: 1320000
A39: Engineering & Survey | B39: 83000
A40: Total Soft Costs | B40: =SUM(B38:B39) -> 1403000
A42: MUD BOND ASSUMPTIONS
A43: MUD Bond Principal — Total | B43: 23400000
A44: MUD Operation Cost | B44: 240000
A45: Third Party / Legal | B45: 150000
A47: CONSTRUCTION LOAN
...

Sheet Total Budget
A1: INTERNATIONAL TRADE PARK HOUSTON — TOTAL PROJECT BUDGET
A2: Land · Horizontal Improvements · Soft Costs · Vertical · Financing · Contingency
A4: TOTAL BUDGET SUMMARY
A5: Budget Category | B5: Budget Amount | C5: $ / Lot | D5: $ / SF | E5: % Total | F5: % HC | G5: Status | H5: Notes
A6: 1. LAND ACQUISITION
A7: Deemed Land Value (EP Contribution) | B7: =Assumptions!B56 -> 11387289 | C7: =IF(Assumptions!B10>0,B7/Assumptions!B10,0) -> 379576.3 | D7: =IF(Assumptions!B9>0,B7/Assumptions!B9,0) -> 2.6251875 | E7: =IF(B49>0,B7/B49,0) -> 0.28730699 | H7: land equity
A8: Land Carry / Holding Costs | B8: 0 | C8: =IF(Assumptions!B10>0,B8/Assumptions!B10,0) -> 0 | D8: =IF(Assumptions!B9>0,B8/Assumptions!B9,0) -> 0 | E8: =IF(B49>0,B8/B49,0) -> 0 | H8: if any cash cost
A9: Due Diligence / Environmental | B9: 0 | C9: =IF(Assumptions!B10>0,B9/Assumptions!B10,0) -> 0 | D9: =IF(Assumptions!B9>0,B9/Assumptions!B9,0) -> 0 | E9: =IF(B49>0,B9/B49,0) -> 0 | H9: Phase I/II ESA
A10: Closing Costs | B10: 0 | C10: =IF(Assumptions!B10>0,B10/Assumptions!B10,0) -> 0 | D10: =IF(Assumptions!B9>0,B10/Assumptions!B9,0) -> 0 | E10: =IF(B49>0,B10/B49,0) -> 0
A11: TOTAL LAND | B11: =SUM(B7:B10) -> 11387289 | C11: =IF(Assumptions!B10>0,B11/Assumptions!B10,0) -> 379576.3 | D11: =IF(Assumptions!B9>0,B11/Assumptions!B9,0) -> 2.6251875 | E11: =IF(B49>0,B11/B49,0) -> 0.28730699
A13: 2. HORIZONTAL IMPROVEMENTS (HARD COSTS)
A14: Water System | B14: =Assumptions!B29 -> 1993000 | C14: =IF(Assumptions!B10>0,B14/Assumptions!B10,0) -> 66433.333 | D14: =IF(Assumptions!B9>0,B14/Assumptions!B9,0) -> 0.45945955 | E14: =IF(B49>0,B14/B49,0) -> 0.050284386 | F14: =IF(Assumptions!B35>0,B14/Assumptions!B35,0) -> 0.084489607 | H14: Potable water distribution
A15: Sanitary Sewer | B15: =Assumptions!B30 -> 3432000 | C15: =IF(Assumptions!B10>0,B15/Assumptions!B10,0) -> 114400 | D15: =IF(Assumptions!B9>0,B15/Assumptions!B9,0) -> 0.7912018 | E15: =IF(B49>0,B15/B49,0) -> 0.086591076 | F15: =IF(Assumptions!B35>0,B15/Assumptions!B35,0) -> 0.14549339 | H15: Gravity sewer + lift stations
A16: Storm Sewer / Detention | B16: =Assumptions!B31 -> 12527000 | C16: =IF(Assumptions!B10>0,B16/Assumptions!B10,0) -> 417566.67 | D16: =IF(Assumptions!B9>0,B16/Assumptions!B9,0) -> 2.8879327 | E16: =IF(B49>0,B16/B49,0) -> 0.31606247 | F16: =IF(Assumptions!B35>0,B16/Assumptions!B35,0) -> 0.53105936 | H16: Detention pond + storm mains
A17: Roadway & Paving | B17: =Assumptions!B32 -> 5098000 | C17: =IF(Assumptions!B10>0,B17/Assumptions!B10,0) -> 169933.33 | D17: =IF(Assumptions!B9>0,B17/Assumptions!B9,0) -> 1.1752759 | E17: =IF(B49>0,B17/B49,0) -> 0.12862509 | F17: =IF(Assumptions!B35>0,B17/Assumptions!B35,0) -> 0.21612043 | H17: Internal roads + curb & gutter
A18: Erosion Control / SWPPP | B18: =Assumptions!B33 -> 262000 | C18: =IF(Assumptions!B10>0,B18/Assumptions!B10,0) -> 8733.3333 | D18: =IF(Assumptions!B9>0,B18/Assumptions!B9,0) -> 0.060400604 | E18: =IF(B49>0,B18/B49,0) -> 0.006610391 | F18: =IF(Assumptions!B35>0,B18/Assumptions!B35,0) -> 0.011107013 | H18: Silt fence, BMP measures
A19: Contingency (Hard) | B19: =Assumptions!B34 -> 276700 | C19: =IF(Assumptions!B10>0,B19/Assumptions!B10,0) -> 9223.3333 | D19: =IF(Assumptions!B9>0,B19/Assumptions!B9,0) -> 0.063789492 | E19: =IF(B49>0,B19/B49,0) -> 0.0069812793 | F19: =IF(Assumptions!B35>0,B19/Assumptions!B35,0) -> 0.011730193 | H19: ~1.2% of hard costs
A20: TOTAL HORIZONTAL IMPROVEMENTS | B20: =Assumptions!B35 -> 23588700 | C20: =IF(Assumptions!B10>0,B20/Assumptions!B10,0) -> 786290 | D20: =IF(Assumptions!B9>0,B20/Assumptions!B9,0) -> 5.43806 | E20: =IF(B49>0,B20/B49,0) -> 0.59515469 | F20: =1 -> 1
A22: 3. SOFT COSTS
A23: Testing / Materials Inspection | B23: =Assumptions!B38 -> 1320000 | C23: =IF(Assumptions!B10>0,B23/Assumptions!B10,0) -> 44000 | D23: =IF(Assumptions!B9>0,B23/Assumptions!B9,0) -> 0.30430838 | E23: =IF(B49>0,B23/B49,0) -> 0.03330426 | H23: Geotech, compaction, materials
A24: Engineering & Survey | B24: =Assumptions!B39 -> 83000 | C24: =IF(Assumptions!B10>0,B24/Assumptions!B10,0) -> 2766.6667 | D24: =IF(Assumptions!B9>0,B24/Assumptions!B9,0) -> 0.019134542 | E24: =IF(B49>0,B24/B49,0) -> 0.0020941315 | H24: Civil engineering, platting
A25: Architecture / Vertical Design | B25: 0 | C25: =IF(Assumptions!B10>0,B25/Assumptions!B10,0) -> 0 | D25: =IF(Assumptions!B9>0,B25/Assumptions!B9,0) -> 0 | E25: =IF(B49>0,B25/B49,0) -> 0 | H25: N/A — land only
A26: Permitting & Fees | B26: 0 | C26: =IF(Assumptions!B10>0,B26/Assumptions!B10,0) -> 0 | D26: =IF(Assumptions!B9>0,B26/Assumptions!B9,0) -> 0 | E26: =IF(B49>0,B26/B49,0) -> 0 | H26: City/county permits
A27: Contingency (Soft) | B27: 0 | C27: =IF(Assumptions!B10>0,B27/Assumptions!B10,0) -> 0 | D27: =IF(Assumptions!B9>0,B27/Assumptions!B9,0) -> 0 | E27: =IF(B49>0,B27/B49,0) -> 0
A28: TOTAL SOFT COSTS | B28: =SUM(B23:B27) -> 1403000 | C28: =IF(Assumptions!B10>0,B28/Assumptions!B10,0) -> 46766.667 | D28: =IF(Assumptions!B9>0,B28/Assumptions!B9,0) -> 0.32344293 | E28: =IF(B49>0,B28/B49,0) -> 0.035398391
A30: 4. VERTICAL CONSTRUCTION
A31: Industrial Buildings (shell) | B31: 0 | C31: =IF(Assumptions!B10>0,B31/Assumptions!B10,0) -> 0 | D31: =IF(Assumptions!B9>0,B31/Assumptions!B9,0) -> 0 | E31: =IF(B49>0,B31/B49,0) -> 0 | H31: Future Phase — land sale only
A32: Retail Shell / Pad Sites | B32: 0 | C32: =IF(Assumptions!B10>0,B32/Assumptions!B10,0) -> 0 | D32: =IF(Assumptions!B9>0,B32/Assumptions!B9,0) -> 0 | E32: =IF(B49>0,B32/B49,0) -> 0 | H32: Future Phase — pad sale only
A33: Multifamily Structures | B33: 0 | C33: =IF(Assumptions!B10>0,B33/Assumptions!B10,0) -> 0 | D33: =IF(Assumptions!B9>0,B33/Assumptions!B9,0) -> 0 | E33: =IF(B49>0,B33/B49,0) -> 0 | H33: Future Phase — lot sale only
A34: Shared Amenities / Landscaping | B34: 0 | C34: =IF(Assumptions!B10>0,B34/Assumptions!B10,0) -> 0 | D34: =IF(Assumptions!B9>0,B34/Assumptions!B9,0) -> 0 | E34: =IF(B49>0,B34/B49,0) -> 0
A35: Vertical Contingency | B35: 0 | C35: =IF(Assumptions!B10>0,B35/Assumptions!B10,0) -> 0 | D35: =IF(Assumptions!B9>0,B35/Assumptions!B9,0) -> 0 | E35: =IF(B49>0,B35/B49,0) -> 0
A36: TOTAL VERTICAL CONSTRUCTION | B36: =SUM(B31:B35) -> 0 | C36: =IF(Assumptions!B10>0,B36/Assumptions!B10,0) -> 0 | D36: =IF(Assumptions!B9>0,B36/Assumptions!B9,0) -> 0 | E36: =IF(B49>0,B36/B49,0) -> 0
A38: 5. FINANCING & TRANSACTION COSTS
A39: Developer Fee (5%) | B39: ='Dev Budget'!B19 -> 1249585 | C39: =IF(Assumptions!B10>0,B39/Assumptions!B10,0) -> 41652.833 | D39: =IF(Assumptions!B9>0,B39/Assumptions!B9,0) -> 0.28807515 | E39: =IF(B49>0,B39/B49,0) -> 0.031527654 | H39: 5% of HC + SC
A40: Loan Broker Fee | B40: =Assumptions!B49 -> 6700 | C40: =IF(Assumptions!B10>0,B40/Assumptions!B10,0) -> 223.33333 | D40: =IF(Assumptions!B9>0,B40/Assumptions!B9,0) -> 0.0015445956 | E40: =IF(B49>0,B40/B49,0) -> 0.00016904435
A41: Lender Fee / Origination | B41: =Assumptions!B50 -> 6700 | C41: =IF(Assumptions!B10>0,B41/Assumptions!B10,0) -> 223.33333 | D41: =IF(Assumptions!B9>0,B41/Assumptions!B9,0) -> 0.0015445956 | E41: =IF(B49>0,B41/B49,0) -> 0.00016904435
A42: Loan Interest | B42: =Assumptions!B53 -> 25800 | C42: =IF(Assumptions!B10>0,B42/Assumptions!B10,0) -> 860 | D42: =IF(Assumptions!B9>0,B42/Assumptions!B9,0) -> 0.0059478457 | E42: =IF(B49>0,B42/B49,0) -> 0.0006509469 | H42: 11% on peak draw
A43: MUD District Operation | B43: =Assumptions!B44 -> 240000 | C43: =IF(Assumptions!B10>0,B43/Assumptions!B10,0) -> 8000 | D43: =IF(Assumptions!B9>0,B43/Assumptions!B9,0) -> 0.055328797 | E43: =IF(B49>0,B43/B49,0) -> 0.00605532 | H43: Bond-funded ops reserve
A44: Third Party / Bond Counsel | B44: =Assumptions!B45 -> 150000 | C44: =IF(Assumptions!B10>0,B44/Assumptions!B10,0) -> 5000 | D44: =IF(Assumptions!B9>0,B44/Assumptions!B9,0) -> 0.034580498 | E44: =IF(B49>0,B44/B49,0) -> 0.003784575
A45: Title & Closing | B45: =Assumptions!B51 -> 1178 | C45: =IF(Assumptions!B10>0,B45/Assumptions!B10,0) -> 39.266667 | D45: =IF(Assumptions!B9>0,B45/Assumptions!B9,0) -> 0.00027157218 | E45: =IF(B49>0,B45/B49,0) -> 2.9721529e-05
...

Sheet Land
A1: INTERNATIONAL TRADE PARK HOUSTON — LAND ANALYSIS
A2: Parcel Summary · Acres by Use · Value/SF · Absorption
A4: SITE OVERVIEW
A5: Total Gross Acres | B5: =Assumptions!B7 -> 136 | D5: Including roads, drainage, common areas
A6: Net Lot Acres (Saleable) | B6: =Assumptions!B8 -> 99.58 | D6: Lots available for sale
A7: Net Lot SF | B7: =Assumptions!B9 -> 4337705 | D7: =IF(Assumptions!B9>0,Assumptions!B9/Assumptions!B10,0) -> 144590.17
A8: Gross-to-Net Ratio | B8: =Assumptions!B8/Assumptions!B7 -> 0.73220588 | D8: Net / Gross
A9: Total Lots | B9: =Assumptions!B10 -> 30 | D9: All product types
A10: Average Lot Size (SF) | B10: =Assumptions!B9/Assumptions!B10 -> 144590.17 | D10: Avg across all types
A11: Average Lot Size (Acres) | B11: =Assumptions!B8/Assumptions!B10 -> 3.3193333
A13: LOT BREAKDOWN BY TYPE
A14: Use Type | B14: Lots | C14: Acres | D14: SF | E14: % Site | F14: Avg Lot SF | G14: Price/SF | H14: Gross Value | I14: $/Acre
A15: Industrial | B15: =Assumptions!B14 -> 8 | C15: =Assumptions!C14 -> 27.6 | D15: =C15*43560 -> 1202256 | E15: =C15/Assumptions!B8 -> 0.27716409 | F15: =D15/B15 -> 150282 | G15: =Assumptions!D14 -> 7.653 | H15: =Assumptions!E14 -> 9190000 | I15: =H15/C15 -> 332971.01
A16: Retail | B16: =Assumptions!B15 -> 18 | C16: =Assumptions!C15 -> 23.5 | D16: =C16*43560 -> 1023660 | E16: =C16/Assumptions!B8 -> 0.23599116 | F16: =D16/B16 -> 56870 | G16: =Assumptions!D15 -> 14.556 | H16: =Assumptions!E15 -> 14900000 | I16: =H16/C16 -> 634042.55
A17: Multifamily | B17: =Assumptions!B16 -> 4 | C17: =Assumptions!C16 -> 48.5 | D17: =C17*43560 -> 2112660 | E17: =C17/Assumptions!B8 -> 0.48704559 | F17: =D17/B17 -> 528165 | G17: =Assumptions!D16 -> 7.242 | H17: =Assumptions!E16 -> 15300437 | I17: =H17/C17 -> 315472.93
A18: TOTAL | B18: =SUM(B15:B17) -> 30 | C18: =SUM(C15:C17) -> 99.6 | D18: =SUM(D15:D17) -> 4338576 | E18: =1 -> 1 | H18: =SUM(H15:H17) -> 39390437 | I18: =H18/C18 -> 395486.32
A20: LAND VALUE ANALYSIS
A21: Metric | B21: Value | C21: Note
A22: Deemed Land Value (EP Equity) | B22: =Assumptions!B56 -> 11387289 | C22: Non-cash equity contribution
A23: Gross Lot Value (As-Developed) | B23: =Assumptions!E17 -> 39390437 | C23: Sum of all lot types
A24: Land Residual (Gross - Deemed) | B24: =Assumptions!E17-Assumptions!B56 -> 28003148 | C24: Uplift from development
A25: Land Value / Gross Acre | B25: =Assumptions!B56/Assumptions!B7 -> 83730.066
A26: Land Value / Net SF | B26: =Assumptions!B56/Assumptions!B9 -> 2.6251875
A27: Land-to-Value Ratio | B27: =Assumptions!B56/Assumptions!E17 -> 0.28908765 | C27: Land cost / As-built value
A28: Net Lot Value (After 4% Comm) | B28: =Assumptions!E17*(1-Assumptions!B60) -> 37814820
A29: Net Revenue / Acre (Saleable) | B29: =Assumptions!E17*(1-Assumptions!B60)/Assumptions!B8 -> 379743.12
A31: ABSORPTION & SALES SCHEDULE
A32: Phase | B32: Start Mo | C32: End Mo | D32: # Lots | E32: Lots/Mo | F32: Revenue | G32: Cumul Rev
A33: Industrial Lots | B33: =Assumptions!B23 -> 5 | C33: =Assumptions!B24 -> 22 | D33: =Assumptions!B14 -> 8 | E33: =Assumptions!B14/(Assumptions!B24-Assumptions!B23+1) -> 0.44444444 | F33: =Assumptions!E14 -> 9190000 | G33: =F33 -> 9190000
A34: Retail Lots | B34: =Assumptions!B23 -> 5 | C34: =Assumptions!B24 -> 22 | D34: =Assumptions!B15 -> 18 | E34: =Assumptions!B15/(Assumptions!B24-Assumptions!B23+1) -> 1 | F34: =Assumptions!E15 -> 14900000 | G34: =G33+F34 -> 24090000
A35: Multifamily Lots | B35: =Assumptions!B23 -> 5 | C35: =Assumptions!B24 -> 22 | D35: =Assumptions!B16 -> 4 | E35: =Assumptions!B16/(Assumptions!B24-Assumptions!B23+1) -> 0.22222222 | F35: =Assumptions!E16 -> 15300437 | G35: =G34+F35 -> 39390437
A36: TOTAL LOTS / REVENUE | D36: =SUM(D33:D35) -> 30 | F36: =Assumptions!E17 -> 39390437 | G36: =Assumptions!E17 -> 39390437

Sheet Improvements
A1: INTERNATIONAL TRADE PARK HOUSTON — IMPROVEMENTS BUDGET
A2: Horizontal Infrastructure · Unit Costs · Timeline · Soft Costs
A4: HORIZONTAL INFRASTRUCTURE (HARD COSTS)
A5: System / Description | B5: Budget | C5: $ / Lot | D5: $ / SF | E5: % HC | F5: Start Mo | G5: End Mo | H5: Duration | I5: Notes
A6: Water System | B6: =Assumptions!B29 -> 1993000 | C6: =IF(Assumptions!B10>0,B6/Assumptions!B10,0) -> 66433.333 | D6: =IF(Assumptions!B9>0,B6/Assumptions!B9,0) -> 0.45945955 | E6: =IF(Assumptions!B35>0,B6/Assumptions!B35,0) -> 0.084489607 | F6: 1 | G6: 18 | H6: =G6-F6+1 -> 18 | I6: Potable water mains, valves, fire hydrants, meters
A7: Sanitary Sewer | B7: =Assumptions!B30 -> 3432000 | C7: =IF(Assumptions!B10>0,B7/Assumptions!B10,0) -> 114400 | D7: =IF(Assumptions!B9>0,B7/Assumptions!B9,0) -> 0.7912018 | E7: =IF(Assumptions!B35>0,B7/Assumptions!B35,0) -> 0.14549339 | F7: 1 | G7: 20 | H7: =G7-F7+1 -> 20 | I7: Gravity collection, manholes, lift station
A8: Storm Sewer & Detention | B8: =Assumptions!B31 -> 12527000 | C8: =IF(Assumptions!B10>0,B8/Assumptions!B10,0) -> 417566.67 | D8: =IF(Assumptions!B9>0,B8/Assumptions!B9,0) -> 2.8879327 | E8: =IF(Assumptions!B35>0,B8/Assumptions!B35,0) -> 0.53105936 | F8: 1 | G8: 24 | H8: =G8-F8+1 -> 24 | I8: Inlets, mains, detention pond, outlet
A9: Roadway & Paving | B9: =Assumptions!B32 -> 5098000 | C9: =IF(Assumptions!B10>0,B9/Assumptions!B10,0) -> 169933.33 | D9: =IF(Assumptions!B9>0,B9/Assumptions!B9,0) -> 1.1752759 | E9: =IF(Assumptions!B35>0,B9/Assumptions!B35,0) -> 0.21612043 | F9: 6 | G9: 30 | H9: =G9-F9+1 -> 25 | I9: Sub-base, base, asphalt, curb & gutter, striping
A10: Erosion Control / SWPPP | B10: =Assumptions!B33 -> 262000 | C10: =IF(Assumptions!B10>0,B10/Assumptions!B10,0) -> 8733.3333 | D10: =IF(Assumptions!B9>0,B10/Assumptions!B9,0) -> 0.060400604 | E10: =IF(Assumptions!B35>0,B10/Assumptions!B35,0) -> 0.011107013 | F10: 1 | G10: 48 | H10: =G10-F10+1 -> 48 | I10: Continuous SWPPP compliance, 50-month project
A11: Contingency — Hard | B11: =Assumptions!B34 -> 276700 | C11: =IF(Assumptions!B10>0,B11/Assumptions!B10,0) -> 9223.3333 | D11: =IF(Assumptions!B9>0,B11/Assumptions!B9,0) -> 0.063789492 | E11: =IF(Assumptions!B35>0,B11/Assumptions!B35,0) -> 0.011730193 | F11: 1 | G11: 50 | H11: =G11-F11+1 -> 50 | I11: ~1.2% of base hard costs
A12: TOTAL HARD COSTS | B12: =Assumptions!B35 -> 23588700 | C12: =IF(Assumptions!B10>0,B12/Assumptions!B10,0) -> 786290 | D12: =IF(Assumptions!B9>0,B12/Assumptions!B9,0) -> 5.43806 | E12: =1 -> 1
A14: SOFT COSTS DETAIL
A15: Description | B15: Budget | C15: $ / Lot | D15: $ / SF | E15: % Soft | F15: Basis | I15: Notes
A16: Testing & Special Inspection | B16: =Assumptions!B38 -> 1320000 | C16: =IF(Assumptions!B10>0,B16/Assumptions!B10,0) -> 44000 | D16: =IF(Assumptions!B9>0,B16/Assumptions!B9,0) -> 0.30430838 | E16: =IF(SUM(B16:B21)>0,B16/SUM(B16:B21),0) -> 0.73619632 | I16: Soils, concrete, asphalt testing, geo report
A17: Civil Engineering & Survey | B17: =Assumptions!B39 -> 83000 | C17: =IF(Assumptions!B10>0,B17/Assumptions!B10,0) -> 2766.6667 | D17: =IF(Assumptions!B9>0,B17/Assumptions!B9,0) -> 0.019134542 | E17: =IF(SUM(B16:B22)>0,B17/SUM(B16:B22),0) -> 0.023145566 | I17: Site design, grading, platting, as-builts
A18: Permitting & Impact Fees | B18: 0 | C18: =IF(Assumptions!B10>0,B18/Assumptions!B10,0) -> 0 | D18: =IF(Assumptions!B9>0,B18/Assumptions!B9,0) -> 0 | E18: =IF(SUM(B16:B23)>0,B18/SUM(B16:B23),0) -> 0 | I18: Included in hard cost estimate
A19: MUD District Formation | B19: =Assumptions!B44 -> 240000 | C19: =IF(Assumptions!B10>0,B19/Assumptions!B10,0) -> 8000 | D19: =IF(Assumptions!B9>0,B19/Assumptions!B9,0) -> 0.055328797 | E19: =IF(SUM(B16:B24)>0,B19/SUM(B16:B24),0) -> 0.0082850899 | I19: PID/MUD creation & admin
A20: Bond Counsel / Legal | B20: =Assumptions!B45 -> 150000 | C20: =IF(Assumptions!B10>0,B20/Assumptions!B10,0) -> 5000 | D20: =IF(Assumptions!B9>0,B20/Assumptions!B9,0) -> 0.034580498 | E20: =IF(SUM(B16:B25)>0,B20/SUM(B16:B25),0) -> 0.0051781812 | I20: MUD bond issuance counsel
A21: Environmental (Phase I/II) | B21: 0 | C21: =IF(Assumptions!B10>0,B21/Assumptions!B10,0) -> 0 | D21: =IF(Assumptions!B9>0,B21/Assumptions!B9,0) -> 0 | E21: =IF(SUM(B16:B26)>0,B21/SUM(B16:B26),0) -> 0 | I21: Completed pre-acquisition
A22: TOTAL SOFT COSTS | B22: =SUM(B16:B21) -> 1793000 | C22: =IF(Assumptions!B10>0,B22/Assumptions!B10,0) -> 59766.667 | D22: =IF(Assumptions!B9>0,B22/Assumptions!B9,0) -> 0.41335222 | E22: =1 -> 1
A24: TOTAL IMPROVEMENTS BUDGET (H+S) | B24: =B12+B22 -> 25381700 | C24: =IF(Assumptions!B10>0,B24/Assumptions!B10,0) -> 846056.67 | D24: =IF(Assumptions!B9>0,B24/Assumptions!B9,0) -> 5.8514122
A26: UNIT COST BENCHMARKS
A27: System | B27: Budget | C27: Linear Feet Est. | D27: $/LF | E27: $/Acre
A28: Water (est. 12,000 LF) | B28: =Assumptions!B29 -> 1993000 | C28: 12000 | D28: =IF(C28>0,B28/C28,0) -> 166.08333 | E28: =IF(Assumptions!B7>0,B28/Assumptions!B7,0) -> 14654.412
A29: Sanitary Sewer (9,000 LF) | B29: =Assumptions!B30 -> 3432000 | C29: 9000 | D29: =IF(C29>0,B29/C29,0) -> 381.33333 | E29: =IF(Assumptions!B7>0,B29/Assumptions!B7,0) -> 25235.294
A30: Storm Sewer (8,000 LF) | B30: =Assumptions!B31 -> 12527000 | C30: 8000 | D30: =IF(C30>0,B30/C30,0) -> 1565.875 | E30: =IF(Assumptions!B7>0,B30/Assumptions!B7,0) -> 92110.294
A31: Roadway (6,000 LF) | B31: =Assumptions!B32 -> 5098000 | C31: 6000 | D31: =IF(C31>0,B31/C31,0) -> 849.66667 | E31: =IF(Assumptions!B7>0,B31/Assumptions!B7,0) -> 37485.294

Sheet Sources & Uses
A1: INTERNATIONAL TRADE PARK HOUSTON — SOURCES & USES OF CAPITAL
A2: Balancing Statement · Tranche Detail · Draw Schedule · Coverage Ratios
A4: USES OF CAPITAL | E4: SOURCES OF CAPITAL
A5: Category | B5: Amount | C5: % Total | E5: Source / Tranche | F5: Amount | G5: % Total
A6: LAND | E6: EQUITY
A7: Deemed Land (EP Equity) | B7: =Assumptions!B56 -> 11387289 | C7: =IF(B30>0,B7/B30,0) -> 0.29920133 | E7: EP Deemed Land Contribution | F7: =Assumptions!B56 -> 11387289 | G7: Non-cash equity; 100% of equity tranche
A8: HARD COSTS | E8: Developer Cash Equity | F8: 0 | G8: Zero cash required from developer
A9: Water System | B9: =Assumptions!B29 -> 1993000 | C9: =IF(B30>0,B9/B30,0) -> 0.052366129 | E9: Total Equity | F9: =Assumptions!B56 -> 11387289
A10: Sanitary Sewer | B10: =Assumptions!B30 -> 3432000 | C10: =IF(B30>0,B10/B30,0) -> 0.090175893 | E10: MUD BOND PROCEEDS
A11: Storm Sewer / Detention | B11: =Assumptions!B31 -> 12527000 | C11: =IF(B30>0,B11/B30,0) -> 0.32914727 | E11: MUD Bond Issuance #1 (Mo 15) | F11: =Assumptions!B43*0.5 -> 11700000 | G11: First \$11.7M — Nov 2027
A12: Roadway & Paving | B12: =Assumptions!B32 -> 5098000 | C12: =IF(B30>0,B12/B30,0) -> 0.13395009 | E12: MUD Bond Issuance #2 (Mo 21) | F12: =Assumptions!B43*0.5 -> 11700000 | G12: Second \$11.7M — May 2028
A13: Erosion Control | B13: =Assumptions!B33 -> 262000 | C13: =IF(B30>0,B13/B30,0) -> 0.0068840571 | E13: Total MUD Bonds | F13: =Assumptions!B43 -> 23400000 | G13: Reimburses eligible costs
A14: Contingency | B14: =Assumptions!B34 -> 276700 | C14: =IF(B30>0,B14/B30,0) -> 0.0072703 | E14: CONSTRUCTION LOAN
A15: Total Hard Costs | B15: =Assumptions!B35 -> 23588700 | C15: =IF(B44>0,B15/B44,0) -> 0 | E15: Peak Loan Balance | F15: =Assumptions!B52 -> 671535 | G15: 11% interest rate
A16: SOFT COSTS | E16: Funded from Lot Sales | F16: =Assumptions!E17*(1-Assumptions!B60) -> 37814820 | G16: Net lot proceeds repay loan
A17: Testing / Inspection | B17: =Assumptions!B38 -> 1320000 | C17: =IF(B30>0,B17/B30,0) -> 0.034683036 | E17: Total Loan / Lot Proceeds | F17: =Assumptions!E17*(1-Assumptions!B60) -> 37814820
A18: Engineering & Survey | B18: =Assumptions!B39 -> 83000 | C18: =IF(B30>0,B18/B30,0) -> 0.0021808273 | E18: REVENUE (SURPLUS)
A19: Total Soft Costs | B19: =Assumptions!B40 -> 1403000 | C19: =IF(B48>0,B19/B48,0) -> 0 | E19: Lot Sales Net Revenue | F19: =Assumptions!E17*(1-Assumptions!B60) -> 37814820
A20: DEVELOPER FEE | E20: MUD Bond Proceeds | F20: =Assumptions!B43 -> 23400000 | G20: Reimbursement of HC
A21: Dev Fee (5% HC+SC) | B21: ='Dev Budget'!B19 -> 1249585 | C21: =IF(B30>0,B21/B30,0) -> 0.03283288 | E21: Total Revenue | F21: =Assumptions!E17*(1-Assumptions!B60)+Assumptions!B43 -> 61214820
A22: FINANCE COSTS
A23: Loan Broker Fee | B23: =Assumptions!B49 -> 6700 | C23: =IF(B30>0,B23/B30,0) -> 0.00017604268
A24: Lender Fee | B24: =Assumptions!B50 -> 6700 | C24: =IF(B30>0,B24/B30,0) -> 0.00017604268
A25: Loan Interest | B25: =Assumptions!B53 -> 25800 | C25: =IF(B30>0,B25/B30,0) -> 0.0006778957
A26: MUD Operation | B26: =Assumptions!B44 -> 240000 | C26: =IF(B30>0,B26/B30,0) -> 0.0063060065
A27: Third Party / Legal | B27: =Assumptions!B45 -> 150000 | C27: =IF(B30>0,B27/B30,0) -> 0.0039412541
A28: Title & Closing | B28: =Assumptions!B51 -> 1178 | C28: =IF(B30>0,B28/B30,0) -> 3.0951982e-05
A29: Total Finance Costs | B29: ='Dev Budget'!B27 -> 430378 | C29: =IF(B58>0,B29/B58,0) -> 0
A30: TOTAL USES | B30: ='Dev Budget'!B30 -> 38058952 | C30: =1 -> 1
A33: BALANCING CHECK & COVERAGE RATIOS
A34: Total Uses of Capital | B34: ='Dev Budget'!B30 -> 38058952
A35: Total MUD + Equity Sources | B35: =Assumptions!B43+Assumptions!B56 -> 34787289
A36: Total Lot Sale Proceeds | B36: =Assumptions!E17*(1-Assumptions!B60) -> 37814820
A37: Total All Sources | B37: =Assumptions!B43+Assumptions!B56+Assumptions!E17*(1-Assumptions!B60) -> 72602109
A38: Net Surplus / (Deficit) | B38: =Assumptions!E17*(1-Assumptions!B60)+Assumptions!B43-'Dev Budget'!B30 -> 23155868 | C38: Positive = project cash-on-cash positive
A39: MUD Coverage Ratio (Bonds/HC) | B39: =Assumptions!B43/Assumptions!B35 -> 0.99200041
A40: Equity Coverage Ratio | B40: =Assumptions!B56/'Dev Budget'!B30 -> 0.29920133
A41: Loan-to-Cost | B41: =Assumptions!B52/'Dev Budget'!B30 -> 0.0176446
A42: Break-Even Lot Price/SF | B42: =('Dev Budget'!B30-Assumptions!B43)/(Assumptions!B9*(1-Assumptions!B60)) -> 3.5202352

Sheet Monthly Cash Flow
A1: INTERNATIONAL TRADE PARK HOUSTON — MONTHLY CASH FLOW
A2: 50-Month Timeline · Capital Draws · MUD Bonds · Lot Sale Receipts · Loan Balance
A4: LINE ITEM | B4: Feb-26 | C4: Mar-26 | D4: Apr-26 | E4: May-26 | F4: Jun-26 | G4: Jul-26 | H4: Aug-26 | I4: Sep-26 | J4: Oct-26 | K4: Nov-26 | L4: Dec-26 | M4: Jan-27 | N4: Feb-27 | O4: Mar-27 | P4: Apr-27 | Q4: May-27 | R4: Jun-27 | S4: Jul-27 | T4: Aug-27 | U4: Sep-27 | V4: Oct-27 | W4: Nov-27 | X4: Dec-27 | Y4: Jan-28 | Z4: Feb-28 | AA4: Mar-28 | AB4: Apr-28 | AC4: May-28 | AD4: Jun-28 | AE4: Jul-28 | AF4: Aug-28 | AG4: Sep-28 | AH4: Oct-28 | AI4: Nov-28 | AJ4: Dec-28 | AK4: Jan-29 | AL4: Feb-29 | AM4: Mar-29 | AN4: Apr-29 | AO4: May-29 | AP4: Jun-29 | AQ4: Jul-29 | AR4: Aug-29 | AS4: Sep-29 | AT4: Oct-29 | AU4: Nov-29 | AV4: Dec-29 | AW4: Jan-30 | AX4: Feb-30 | AY4: Mar-30 | AZ4: TOTAL
A5: CAPITAL DRAWS — HARD COSTS
A6: Water System | B6: =Assumptions!B29/12 -> 166083.33 | C6: =Assumptions!B29/12 -> 166083.33 | D6: =Assumptions!B29/12 -> 166083.33 | E6: =Assumptions!B29/12 -> 166083.33 | F6: =Assumptions!B29/12 -> 166083.33 | G6: =Assumptions!B29/12 -> 166083.33 | H6: =Assumptions!B29/12 -> 166083.33 | I6: =Assumptions!B29/12 -> 166083.33 | J6: =Assumptions!B29/12 -> 166083.33 | K6: =Assumptions!B29/12 -> 166083.33 | L6: =Assumptions!B29/12 -> 166083.33 | M6: =Assumptions!B29/12 -> 166083.33 | N6: 0 | O6: 0 | P6: 0 | Q6: 0 | R6: 0 | S6: 0 | T6: 0 | U6: 0 | V6: 0 | W6: 0 | X6: 0 | Y6: 0 | Z6: 0 | AA6: 0 | AB6: 0 | AC6: 0 | AD6: 0 | AE6: 0 | AF6: 0 | AG6: 0 | AH6: 0 | AI6: 0 | AJ6: 0 | AK6: 0 | AL6: 0 | AM6: 0 | AN6: 0 | AO6: 0 | AP6: 0 | AQ6: 0 | AR6: 0 | AS6: 0 | AT6: 0 | AU6: 0 | AV6: 0 | AW6: 0 | AX6: 0 | AY6: 0 | AZ6: =SUM(B6:AY6) -> 1993000
A7: Sanitary Sewer | B7: 0 | C7: =Assumptions!B30/17 -> 201882.35 | D7: =Assumptions!B30/17 -> 201882.35 | E7: =Assumptions!B30/17 -> 201882.35 | F7: =Assumptions!B30/17 -> 201882.35 | G7: =Assumptions!B30/17 -> 201882.35 | H7: =Assumptions!B30/17 -> 201882.35 | I7: =Assumptions!B30/17 -> 201882.35 | J7: =Assumptions!B30/17 -> 201882.35 | K7: =Assumptions!B30/17 -> 201882.35 | L7: =Assumptions!B30/17 -> 201882.35 | M7: =Assumptions!B30/17 -> 201882.35 | N7: =Assumptions!B30/17 -> 201882.35 | O7: =Assumptions!B30/17 -> 201882.35 | P7: =Assumptions!B30/17 -> 201882.35 | Q7: =Assumptions!B30/17 -> 201882.35 | R7: =Assumptions!B30/17 -> 201882.35 | S7: =Assumptions!B30/17 -> 201882.35 | T7: 0 | U7: 0 | V7: 0 | W7: 0 | X7: 0 | Y7: 0 | Z7: 0 | AA7: 0 | AB7: 0 | AC7: 0 | AD7: 0 | AE7: 0 | AF7: 0 | AG7: 0 | AH7: 0 | AI7: 0 | AJ7: 0 | AK7: 0 | AL7: 0 | AM7: 0 | AN7: 0 | AO7: 0 | AP7: 0 | AQ7: 0 | AR7: 0 | AS7: 0 | AT7: 0 | AU7: 0 | AV7: 0 | AW7: 0 | AX7: 0 | AY7: 0 | AZ7: =SUM(B7:AY7) -> 3432000
A8: Storm Sewer / Detention | B8: =Assumptions!B31/24 -> 521958.33 | C8: =Assumptions!B31/24 -> 521958.33 | D8: =Assumptions!B31/24 -> 521958.33 | E8: =Assumptions!B31/24 -> 521958.33 | F8: =Assumptions!B31/24 -> 521958.33 | G8: =Assumptions!B31/24 -> 521958.33 | H8: =Assumptions!B31/24 -> 521958.33 | I8: =Assumptions!B31/24 -> 521958.33 | J8: =Assumptions!B31/24 -> 521958.33 | K8: =Assumptions!B31/24 -> 521958.33 | L8: =Assumptions!B31/24 -> 521958.33 | M8: =Assumptions!B31/24 -> 521958.33 | N8: =Assumptions!B31/24 -> 521958.33 | O8: =Assumptions!B31/24 -> 521958.33 | P8: =Assumptions!B31/24 -> 521958.33 | Q8: =Assumptions!B31/24 -> 521958.33 | R8: =Assumptions!B31/24 -> 521958.33 | S8: =Assumptions!B31/24 -> 521958.33 | T8: =Assumptions!B31/24 -> 521958.33 | U8: =Assumptions!B31/24 -> 521958.33 | V8: =Assumptions!B31/24 -> 521958.33 | W8: =Assumptions!B31/24 -> 521958.33 | X8: =Assumptions!B31/24 -> 521958.33 | Y8: =Assumptions!B31/24 -> 521958.33 | Z8: 0 | AA8: 0 | AB8: 0 | AC8: 0 | AD8: 0 | AE8: 0 | AF8: 0 | AG8: 0 | AH8: 0 | AI8: 0 | AJ8: 0 | AK8: 0 | AL8: 0 | AM8: 0 | AN8: 0 | AO8: 0 | AP8: 0 | AQ8: 0 | AR8: 0 | AS8: 0 | AT8: 0 | AU8: 0 | AV8: 0 | AW8: 0 | AX8: 0 | AY8: 0 | AZ8: =SUM(B8:AY8) -> 12527000
A9: Roadway & Paving | B9: 0 | C9: 0 | D9: 0 | E9: 0 | F9: 0 | G9: =Assumptions!B32/25 -> 203920 | H9: =Assumptions!B32/25 -> 203920 | I9: =Assumptions!B32/25 -> 203920 | J9: =Assumptions!B32/25 -> 203920 | K9: =Assumptions!B32/25 -> 203920 | L9: =Assumptions!B32/25 -> 203920 | M9: =Assumptions!B32/25 -> 203920 | N9: =Assumptions!B32/25 -> 203920 | O9: =Assumptions!B32/25 -> 203920 | P9: =Assumptions!B32/25 -> 203920 | Q9: =Assumptions!B32/25 -> 203920 | R9: =Assumptions!B32/25 -> 203920 | S9: =Assumptions!B32/25 -> 203920 | T9: =Assumptions!B32/25 -> 203920 | U9: =Assumptions!B32/25 -> 203920 | V9: =Assumptions!B32/25 -> 203920 | W9: =Assumptions!B32/25 -> 203920 | X9: =Assumptions!B32/25 -> 203920 | Y9: =Assumptions!B32/25 -> 203920 | Z9: =Assumptions!B32/25 -> 203920 | AA9: =Assumptions!B32/25 -> 203920 | AB9: =Assumptions!B32/25 -> 203920 | AC9: =Assumptions!B32/25 -> 203920 | AD9: =Assumptions!B32/25 -> 203920 | AE9: =Assumptions!B32/25 -> 203920 | AF9: 0 | AG9: 0 | AH9: 0 | AI9: 0 | AJ9: 0 | AK9: 0 | AL9: 0 | AM9: 0 | AN9: 0 | AO9: 0 | AP9: 0 | AQ9: 0 | AR9: 0 | AS9: 0 | AT9: 0 | AU9: 0 | AV9: 0 | AW9: 0 | AX9: 0 | AY9: 0 | AZ9: =SUM(B9:AY9) -> 5098000
A10: Erosion Control | B10: =Assumptions!B33/48 -> 5458.3333 | C10: =Assumptions!B33/48 -> 5458.3333 | D10: =Assumptions!B33/48 -> 5458.3333 | E10: =Assumptions!B33/48 -> 5458.3333 | F10: =Assumptions!B33/48 -> 5458.3333 | G10: =Assumptions!B33/48 -> 5458.3333 | H10: =Assumptions!B33/48 -> 5458.3333 | I10: =Assumptions!B33/48 -> 5458.3333 | J10: =Assumptions!B33/48 -> 5458.3333 | K10: =Assumptions!B33/48 -> 5458.3333 | L10: =Assumptions!B33/48 -> 5458.3333 | M10: =Assumptions!B33/48 -> 5458.3333 | N10: =Assumptions!B33/48 -> 5458.3333 | O10: =Assumptions!B33/48 -> 5458.3333 | P10: =Assumptions!B33/48 -> 5458.3333 | Q10: =Assumptions!B33/48 -> 5458.3333 | R10: =Assumptions!B33/48 -> 5458.3333 | S10: =Assumptions!B33/48 -> 5458.3333 | T10: =Assumptions!B33/48 -> 5458.3333 | U10: =Assumptions!B33/48 -> 5458.3333 | V10: =Assumptions!B33/48 -> 5458.3333 | W10: =Assumptions!B33/48 -> 5458.3333 | X10: =Assumptions!B33/48 -> 5458.3333 | Y10: =Assumptions!B33/48 -> 5458.3333 | Z10: =Assumptions!B33/48 -> 5458.3333 | AA10: =Assumptions!B33/48 -> 5458.3333 | AB10: =Assumptions!B33/48 -> 5458.3333 | AC10: =Assumptions!B33/48 -> 5458.3333 | AD10: =Assumptions!B33/48 -> 5458.3333 | AE10: =Assumptions!B33/48 -> 5458.3333 | AF10: =Assumptions!B33/48 -> 5458.3333 | AG10: =Assumptions!B33/48 -> 5458.3333 | AH10: =Assumptions!B33/48 -> 5458.3333 | AI10: =Assumptions!B33/48 -> 5458.3333 | AJ10: =Assumptions!B33/48 -> 5458.3333 | AK10: =Assumptions!B33/48 -> 5458.3333 | AL10: =Assumptions!B33/48 -> 5458.3333 | AM10: =Assumptions!B33/48 -> 5458.3333 | AN10: =Assumptions!B33/48 -> 5458.3333 | AO10: =Assumptions!B33/48 -> 5458.3333 | AP10: =Assumptions!B33/48 -> 5458.3333 | AQ10: =Assumptions!B33/48 -> 5458.3333 | AR10: =Assumptions!B33/48 -> 5458.3333 | AS10: =Assumptions!B33/48 -> 5458.3333 | AT10: =Assumptions!B33/48 -> 5458.3333 | AU10: =Assumptions!B33/48 -> 5458.3333 | AV10: =Assumptions!B33/48 -> 5458.3333 | AW10: =Assumptions!B33/48 -> 5458.3333 | AX10: 0 | AY10: 0 | AZ10: =SUM(B10:AY10) -> 262000
A11: Contingency | B11: =Assumptions!B34/50 -> 5534 | C11: =Assumptions!B34/50 -> 5534 | D11: =Assumptions!B34/50 -> 5534 | E11: =Assumptions!B34/50 -> 5534 | F11: =Assumptions!B34/50 -> 5534 | G11: =Assumptions!B34/50 -> 5534 | H11: =Assumptions!B34/50 -> 5534 | I11: =Assumptions!B34/50 -> 5534 | J11: =Assumptions!B34/50 -> 5534 | K11: =Assumptions!B34/50 -> 5534 | L11: =Assumptions!B34/50 -> 5534 | M11: =Assumptions!B34/50 -> 5534 | N11: =Assumptions!B34/50 -> 5534 | O11: =Assumptions!B34/50 -> 5534 | P11: =Assumptions!B34/50 -> 5534 | Q11: =Assumptions!B34/50 -> 5534 | R11: =Assumptions!B34/50 -> 5534 | S11: =Assumptions!B34/50 -> 5534 | T11: =Assumptions!B34/50 -> 5534 | U11: =Assumptions!B34/50 -> 5534 | V11: =Assumptions!B34/50 -> 5534 | W11: =Assumptions!B34/50 -> 5534 | X11: =Assumptions!B34/50 -> 5534 | Y11: =Assumptions!B34/50 -> 5534 | Z11: =Assumptions!B34/50 -> 5534 | AA11: =Assumptions!B34/50 -> 5534 | AB11: =Assumptions!B34/50 -> 5534 | AC11: =Assumptions!B34/50 -> 5534 | AD11: =Assumptions!B34/50 -> 5534 | AE11: =Assumptions!B34/50 -> 5534 | AF11: =Assumptions!B34/50 -> 5534 | AG11: =Assumptions!B34/50 -> 5534 | AH11: =Assumptions!B34/50 -> 5534 | AI11: =Assumptions!B34/50 -> 5534 | AJ11: =Assumptions!B34/50 -> 5534 | AK11: =Assumptions!B34/50 -> 5534 | AL11: =Assumptions!B34/50 -> 5534 | AM11: =Assumptions!B34/50 -> 5534 | AN11: =Assumptions!B34/50 -> 5534 | AO11: =Assumptions!B34/50 -> 5534 | AP11: =Assumptions!B34/50 -> 5534 | AQ11: =Assumptions!B34/50 -> 5534 | AR11: =Assumptions!B34/50 -> 5534 | AS11: =Assumptions!B34/50 -> 5534 | AT11: =Assumptions!B34/50 -> 5534 | AU11: =Assumptions!B34/50 -> 5534 | AV11: =Assumptions!B34/50 -> 5534 | AW11: =Assumptions!B34/50 -> 5534 | AX11: =Assumptions!B34/50 -> 5534 | AY11: =Assumptions!B34/50 -> 5534 | AZ11: =SUM(B11:AY11) -> 276700
A12: TOTAL HARD COST DRAWS | B12: =B6+B7+B8+B9+B10+B11 -> 699034 | C12: =C6+C7+C8+C9+C10+C11 -> 900916.35 | D12: =D6+D7+D8+D9+D10+D11 -> 900916.35 | E12: =E6+E7+E8+E9+E10+E11 -> 900916.35 | F12: =F6+F7+F8+F9+F10+F11 -> 900916.35 | G12: =G6+G7+G8+G9+G10+G11 -> 1104836.4 | H12: =H6+H7+H8+H9+H10+H11 -> 1104836.4 | I12: =I6+I7+I8+I9+I10+I11 -> 1104836.4 | ... AZ12: =AZ6+AZ7+AZ8+AZ9+AZ10+AZ11 -> 23588700
A13: CAPITAL DRAWS — SOFT COSTS
A14: Testing / Inspection | B14: =Assumptions!B38/36 -> 36666.667 | C14: =Assumptions!B38/36 -> 36666.667 | D14: =Assumptions!B38/36 -> 36666.667 | E14: =Assumptions!B38/36 -> 36666.667 | F14: =Assumptions!B38/36 -> 36666.667 | G14: =Assumptions!B38/36 -> 36666.667 | H14: =Assumptions!B38/36 -> 36666.667 | I14: =Assumptions!B38/36 -> 36666.667 | J14: =Assumptions!B38/36 -> 36666.667 | K14: =Assumptions!B38/36 -> 36666.667 | L14: =Assumptions!B38/36 -> 36666.667 | M14: =Assumptions!B38/36 -> 36666.667 | N14: =Assumptions!B38/36 -> 36666.667 | O14: =Assumptions!B38/36 -> 36666.667 | P14: =Assumptions!B38/36 -> 36666.667 | Q14: =Assumptions!B38/36 -> 36666.667 | R14: =Assumptions!B38/36 -> 36666.667 | S14: =Assumptions!B38/36 -> 36666.667 | T14: =Assumptions!B38/36 -> 36666.667 | U14: =Assumptions!B38/36 -> 36666.667 | V14: =Assumptions!B38/36 -> 36666.667 | W14: =Assumptions!B38/36 -> 36666.667 | X14: =Assumptions!B38/36 -> 36666.667 | Y14: =Assumptions!B38/36 -> 36666.667 | Z14: =Assumptions!B38/36 -> 36666.667 | AA14: =Assumptions!B38/36 -> 36666.667 | AB14: =Assumptions!B38/36 -> 36666.667 | AC14: =Assumptions!B38/36 -> 36666.667 | AD14: =Assumptions!B38/36 -> 36666.667 | AE14: =Assumptions!B38/36 -> 36666.667 | AF14: =Assumptions!B38/36 -> 36666.667 | AG14: =Assumptions!B38/36 -> 36666.667 | AH14: =Assumptions!B38/36 -> 36666.667 | AI14: =Assumptions!B38/36 -> 36666.667 | AJ14: =Assumptions!B38/36 -> 36666.667 | AK14: =Assumptions!B38/36 -> 36666.667 | AL14: 0 | AM14: 0 | AN14: 0 | AO14: 0 | AP14: 0 | AQ14: 0 | AR14: 0 | AS14: 0 | AT14: 0 | AU14: 0 | AV14: 0 | AW14: 0 | AX14: 0 | AY14: 0 | AZ14: =SUM(B14:AY14) -> 1320000
A15: Engineering & Survey | B15: =Assumptions!B39/12 -> 6916.6667 | C15: =Assumptions!B39/12 -> 6916.6667 | D15: =Assumptions!B39/12 -> 6916.6667 | E15: =Assumptions!B39/12 -> 6916.6667 | F15: =Assumptions!B39/12 -> 6916.6667 | G15: =Assumptions!B39/12 -> 6916.6667 | H15: =Assumptions!B39/12 -> 6916.6667 | I15: =Assumptions!B39/12 -> 6916.6667 | J15: =Assumptions!B39/12 -> 6916.6667 | K15: =Assumptions!B39/12 -> 6916.6667 | L15: =Assumptions!B39/12 -> 6916.6667 | M15: =Assumptions!B39/12 -> 6916.6667 | N15: 0 | O15: 0 | P15: 0 | Q15: 0 | R15: 0 | S15: 0 | T15: 0 | U15: 0 | V15: 0 | W15: 0 | X15: 0 | Y15: 0 | Z15: 0 | AA15: 0 | AB15: 0 | AC15: 0 | AD15: 0 | AE15: 0 | AF15: 0 | AG15: 0 | AH15: 0 | AI15: 0 | AJ15: 0 | AK15: 0 | AL15: 0 | AM15: 0 | AN15: 0 | AO15: 0 | AP15: 0 | AQ15: 0 | AR15: 0 | AS15: 0 | AT15: 0 | AU15: 0 | AV15: 0 | AW15: 0 | AX15: 0 | AY15: 0 | AZ15: =SUM(B15:AY15) -> 83000
A16: TOTAL SOFT COST DRAWS | B16: =B14+B15 -> 43583.333 | C16: =C14+C15 -> 43583.333 | D16: =D14+D15 -> 43583.333 | E16: =E14+E15 -> 43583.333 | F16: =F14+F15 -> 43583.333 | G16: =G14+G15 -> 43583.333 | H16: =H14+H15 -> 43583.333 | I16: =I14+I15 -> 43583.333 | ... AZ16: =AZ14+AZ15 -> 1403000
A17: LOT SALE RECEIPTS
A18: Industrial Lot Sales (Net) | B18: 0 | C18: 0 | D18: 0 | E18: 0 | F18: =Assumptions!E14*(1-Assumptions!B60)/(18) -> 490133.33 | G18: =Assumptions!E14*(1-Assumptions!B60)/(18) -> 490133.33 | H18: =Assumptions!E14*(1-Assumptions!B60)/(18) -> 490133.33 | I18: =Assumptions!E14*(1-Assumptions!B60)/(18) -> 490133.33 | J18: =Assumptions!E14*(1-Assumptions!B60)/(18) -> 490133.33 | K18: =Assumptions!E14*(1-Assumptions!B60)/(18) -> 490133.33 | L18: =Assumptions!E14*(1-Assumptions!B60)/(18) -> 490133.33 | M18: =Assumptions!E14*(1-Assumptions!B60)/(18) -> 490133.33 | N18: =Assumptions!E14*(1-Assumptions!B60)/(18) -> 490133.33 | O18: =Assumptions!E14*(1-Assumptions!B60)/(18) -> 490133.33 | P18: =Assumptions!E14*(1-Assumptions!B60)/(18) -> 490133.33 | Q18: =Assumptions!E14*(1-Assumptions!B60)/(18) -> 490133.33 | R18: =Assumptions!E14*(1-Assumptions!B60)/(18) -> 490133.33 | S18: =Assumptions!E14*(1-Assumptions!B60)/(18) -> 490133.33 | T18: =Assumptions!E14*(1-Assumptions!B60)/(18) -> 490133.33 | U18: =Assumptions!E14*(1-Assumptions!B60)/(18) -> 490133.33 | V18: =Assumptions!E14*(1-Assumptions!B60)/(18) -> 490133.33 | W18: =Assumptions!E14*(1-Assumptions!B60)/(18) -> 490133.33 | X18: 0 | Y18: 0 | Z18: 0 | AA18: 0 | AB18: 0 | AC18: 0 | AD18: 0 | AE18: 0 | AF18: 0 | AG18: 0 | AH18: 0 | AI18: 0 | AJ18: 0 | AK18: 0 | AL18: 0 | AM18: 0 | AN18: 0 | AO18: 0 | AP18: 0 | AQ18: 0 | AR18: 0 | AS18: 0 | AT18: 0 | AU18: 0 | AV18: 0 | AW18: 0 | AX18: 0 | AY18: 0 | AZ18: =SUM(B18:AY18) -> 8822400
A19: Retail Lot Sales (Net) | B19: 0 | C19: 0 | D19: 0 | E19: 0 | F19: =Assumptions!E15*(1-Assumptions!B60)/(18) -> 794666.67 | G19: =Assumptions!E15*(1-Assumptions!B60)/(18) -> 794666.67 | H19: =Assumptions!E15*(1-Assumptions!B60)/(18) -> 794666.67 | I19: =Assumptions!E15*(1-Assumptions!B60)/(18) -> 794666.67 | J19: =Assumptions!E15*(1-Assumptions!B60)/(18) -> 794666.67 | K19: =Assumptions!E15*(1-Assumptions!B60)/(18) -> 794666.67 | L19: =Assumptions!E15*(1-Assumptions!B60)/(18) -> 794666.67 | M19: =Assumptions!E15*(1-Assumptions!B60)/(18) -> 794666.67 | N19: =Assumptions!E15*(1-Assumptions!B60)/(18) -> 794666.67 | O19: =Assumptions!E15*(1-Assumptions!B60)/(18) -> 794666.67 | P19: =Assumptions!E15*(1-Assumptions!B60)/(18) -> 794666.67 | Q19: =Assumptions!E15*(1-Assumptions!B60)/(18) -> 794666.67 | R19: =Assumptions!E15*(1-Assumptions!B60)/(18) -> 794666.67 | S19: =Assumptions!E15*(1-Assumptions!B60)/(18) -> 794666.67 | T19: =Assumptions!E15*(1-Assumptions!B60)/(18) -> 794666.67 | U19: =Assumptions!E15*(1-Assumptions!B60)/(18) -> 794666.67 | V19: =Assumptions!E15*(1-Assumptions!B60)/(18) -> 794666.67 | W19: =Assumptions!E15*(1-Assumptions!B60)/(18) -> 794666.67 | X19: 0 | Y19: 0 | Z19: 0 | AA19: 0 | AB19: 0 | AC19: 0 | AD19: 0 | AE19: 0 | AF19: 0 | AG19: 0 | AH19: 0 | AI19: 0 | AJ19: 0 | AK19: 0 | AL19: 0 | AM19: 0 | AN19: 0 | AO19: 0 | AP19: 0 | AQ19: 0 | AR19: 0 | AS19: 0 | AT19: 0 | AU19: 0 | AV19: 0 | AW19: 0 | AX19: 0 | AY19: 0 | AZ19: =SUM(B19:AY19) -> 14304000
A20: Multifamily Lot Sales (Net) | B20: 0 | C20: 0 | D20: 0 | E20: 0 | F20: =Assumptions!E16*(1-Assumptions!B60)/(18) -> 816023.31 | G20: =Assumptions!E16*(1-Assumptions!B60)/(18) -> 816023.31 | H20: =Assumptions!E16*(1-Assumptions!B60)/(18) -> 816023.31 | I20: =Assumptions!E16*(1-Assumptions!B60)/(18) -> 816023.31 | J20: =Assumptions!E16*(1-Assumptions!B60)/(18) -> 816023.31 | K20: =Assumptions!E16*(1-Assumptions!B60)/(18) -> 816023.31 | L20: =Assumptions!E16*(1-Assumptions!B60)/(18) -> 816023.31 | M20: =Assumptions!E16*(1-Assumptions!B60)/(18) -> 816023.31 | N20: =Assumptions!E16*(1-Assumptions!B60)/(18) -> 816023.31 | O20: =Assumptions!E16*(1-Assumptions!B60)/(18) -> 816023.31 | P20: =Assumptions!E16*(1-Assumptions!B60)/(18) -> 816023.31 | Q20: =Assumptions!E16*(1-Assumptions!B60)/(18) -> 816023.31 | R20: =Assumptions!E16*(1-Assumptions!B60)/(18) -> 816023.31 | S20: =Assumptions!E16*(1-Assumptions!B60)/(18) -> 816023.31 | T20: =Assumptions!E16*(1-Assumptions!B60)/(18) -> 816023.31 | U20: =Assumptions!E16*(1-Assumptions!B60)/(18) -> 816023.31 | V20: =Assumptions!E16*(1-Assumptions!B60)/(18) -> 816023.31 | W20: =Assumptions!E16*(1-Assumptions!B60)/(18) -> 816023.31 | X20: 0 | Y20: 0 | Z20: 0 | AA20: 0 | AB20: 0 | AC20: 0 | AD20: 0 | AE20: 0 | AF20: 0 | AG20: 0 | AH20: 0 | AI20: 0 | AJ20: 0 | AK20: 0 | AL20: 0 | AM20: 0 | AN20: 0 | AO20: 0 | AP20: 0 | AQ20: 0 | AR20: 0 | AS20: 0 | AT20: 0 | AU20: 0 | AV20: 0 | AW20: 0 | AX20: 0 | AY20: 0 | AZ20: =SUM(B20:AY20) -> 14688420
A21: TOTAL LOT SALE RECEIPTS | B21: =B18+B19+B20 -> 0 | C21: =C18+C19+C20 -> 0 | D21: =D18+D19+D20 -> 0 | E21: =E18+E19+E20 -> 0 | F21: =F18+F19+F20 -> 2100823.3 | G21: =G18+G19+G20 -> 2100823.3 | H21: =H18+H19+H20 -> 2100823.3 | I21: =I18+I19+I20 -> 2100823.3 | ... AZ21: =AZ18+AZ19+AZ20 -> 37814820
A22: MUD BOND PROCEEDS
A23: MUD Bond Issuance #1 (Month 15) | B23: 0 | C23: 0 | D23: 0 | E23: 0 | F23: 0 | G23: 0 | H23: 0 | I23: 0 | J23: 0 | K23: 0 | L23: 0 | M23: 0 | N23: 0 | O23: 0 | P23: =Assumptions!B43*0.5 -> 11700000 | Q23: 0 | R23: 0 | S23: 0 | T23: 0 | U23: 0 | V23: 0 | W23: 0 | X23: 0 | Y23: 0 | Z23: 0 | AA23: 0 | AB23: 0 | AC23: 0 | AD23: 0 | AE23: 0 | AF23: 0 | AG23: 0 | AH23: 0 | AI23: 0 | AJ23: 0 | AK23: 0 | AL23: 0 | AM23: 0 | AN23: 0 | AO23: 0 | AP23: 0 | AQ23: 0 | AR23: 0 | AS23: 0 | AT23: 0 | AU23: 0 | AV23: 0 | AW23: 0 | AX23: 0 | AY23: 0 | AZ23: =SUM(B23:AY23) -> 11700000
A24: MUD Bond Issuance #2 (Month 21) | B24: 0 | C24: 0 | D24: 0 | E24: 0 | F24: 0 | G24: 0 | H24: 0 | I24: 0 | J24: 0 | K24: 0 | L24: 0 | M24: 0 | N24: 0 | O24: 0 | P24: 0 | Q24: 0 | R24: 0 | S24: 0 | T24: 0 | U24: 0 | V24: =Assumptions!B43*0.5 -> 11700000 | W24: 0 | X24: 0 | Y24: 0 | Z24: 0 | AA24: 0 | AB24: 0 | AC24: 0 | AD24: 0 | AE24: 0 | AF24: 0 | AG24: 0 | AH24: 0 | AI24: 0 | AJ24: 0 | AK24: 0 | AL24: 0 | AM24: 0 | AN24: 0 | AO24: 0 | AP24: 0 | AQ24: 0 | AR24: 0 | AS24: 0 | AT24: 0 | AU24: 0 | AV24: 0 | AW24: 0 | AX24: 0 | AY24: 0 | AZ24: =SUM(B24:AY24) -> 11700000
A25: TOTAL MUD RECEIPTS | B25: =B23+B24 -> 0 | C25: =C23+C24 -> 0 | D25: =D23+D24 -> 0 | E25: =E23+E24 -> 0 | F25: =F23+F24 -> 0 | G25: =G23+G24 -> 0 | H25: =H23+H24 -> 0 | I25: =I23+I24 -> 0 | ... AZ25: =AZ23+AZ24 -> 23400000
A26: NET CASH FLOW
A27: NET CASH FLOW (Receipts - Draws) | B27: =B21+B25-B12-B16 -> -742617.33 | C27: =C21+C25-C12-C16 -> -944499.69 | D27: =D21+D25-D12-D16 -> -944499.69 | E27: =E21+E25-E12-E16 -> -944499.69 | F27: =F21+F25-F12-F16 -> 1156323.6 | G27: =G21+G25-G12-G16 -> 952403.62 | H27: =H21+H25-H12-H16 -> 952403.62 | I27: =I21+I25-I12-I16 -> 952403.62 | ... AZ27: =AZ21+AZ25-AZ12-AZ16 -> 36223120
A28: CUMULATIVE CASH FLOW | B28: =B27 -> -742617.33 | C28: =B28+C27 -> -1687117 | D28: =C28+D27 -> -2631616.7 | E28: =D28+E27 -> -3576116.4 | F28: =E28+F27 -> -2419792.8 | G28: =F28+G27 -> -1467389.2 | H28: =G28+H27 -> -514985.53 | I28: =H28+I27 -> 437418.09 | J28: =I28+J27 -> 1389821.7 | ... AY28: =AX28+AY27 -> 36223120 | AZ28: =SUM(B27:AY27) -> 36223120
A29: ESTIMATED LOAN BALANCE | B29: =MAX(0,-B28) -> 742617.33 | C29: =MAX(0,-C28) -> 1687117 | D29: =MAX(0,-D28) -> 2631616.7 | E29: =MAX(0,-E28) -> 3576116.4 | F29: =MAX(0,-F28) -> 2419792.8 | G29: =MAX(0,-G28) -> 1467389.2 | H29: =MAX(0,-H28) -> 514985.53 | I29: =MAX(0,-I28) -> 0 | ... AY29: =MAX(0,-AY28) -> 0 | AZ29: =MAX(B29:AY29) -> 3576116.4

Sheet Dev Budget
A1: INTERNATIONAL TRADE PARK HOUSTON — DEVELOPMENT BUDGET
A2: Uses of Funds & Sources of Funds
A4: USES OF FUNDS | F4: SOURCES OF FUNDS
A5: Category | B5: Amount | C5: % of Total | D5: $/SF | F5: Source | G5: Amount
A6: HARD COSTS | F6: MUD Bond Proceeds | G6: =Assumptions!B33 -> 262000
A7: Water System | B7: =Assumptions!B29 -> 1993000 | C7: =IF(B30>0,B7/B30,0) -> 0.052366129 | D7: =IF(Assumptions!B9>0,B7/Assumptions!B9,0) -> 0.45945955 | F7: Equity Partner (Deemed Land) | G7: =Assumptions!B43 -> 23400000
A8: Sanitary Sewer | B8: =Assumptions!B30 -> 3432000 | C8: =IF(B30>0,B8/B30,0) -> 0.090175893 | D8: =IF(Assumptions!B9>0,B8/Assumptions!B9,0) -> 0.7912018 | F8: Construction Loan (Net Draw) | G8: =Assumptions!B41 -> 0
A9: Storm Sewer | B9: =Assumptions!B31 -> 12527000 | C9: =IF(B30>0,B9/B30,0) -> 0.32914727 | D9: =IF(Assumptions!B9>0,B9/Assumptions!B9,0) -> 2.8879327 | F9: TOTAL SOURCES | G9: =SUM(G6:G8) -> 23662000
A10: Roadway | B10: =Assumptions!B32 -> 5098000 | C10: =IF(B30>0,B10/B30,0) -> 0.13395009 | D10: =IF(Assumptions!B9>0,B10/Assumptions!B9,0) -> 1.1752759
A11: Erosion Control | B11: =Assumptions!B33 -> 262000 | C11: =IF(B30>0,B11/B30,0) -> 0.0068840571 | D11: =IF(Assumptions!B9>0,B11/Assumptions!B9,0) -> 0.060400604
A12: Contingency | B12: =Assumptions!B34 -> 276700 | C12: =IF(B30>0,B12/B30,0) -> 0.0072703 | D12: =IF(Assumptions!B9>0,B12/Assumptions!B9,0) -> 0.063789492
A13: Total Hard Costs | B13: =SUM(B7:B12) -> 23588700 | C13: =IF(B30>0,B13/B30,0) -> 0.61979373 | D13: =IF(Assumptions!B9>0,B13/Assumptions!B9,0) -> 5.43806
A14: SOFT COSTS
A15: Testing / Inspection | B15: =Assumptions!B38 -> 1320000 | C15: =IF(B30>0,B15/B30,0) -> 0.034683036 | D15: =IF(Assumptions!B9>0,B15/Assumptions!B9,0) -> 0.30430838
A16: Engineering & Survey | B16: =Assumptions!B39 -> 83000 | C16: =IF(B30>0,B16/B30,0) -> 0.0021808273 | D16: =IF(Assumptions!B9>0,B16/Assumptions!B9,0) -> 0.019134542
A17: Total Soft Costs | B17: =SUM(B15:B16) -> 1403000 | C17: =IF(B30>0,B17/B30,0) -> 0.036863863 | D17: =IF(Assumptions!B9>0,B17/Assumptions!B9,0) -> 0.32344293
A18: Deemed Land Value (EP Contribution) | B18: =Assumptions!B56 -> 11387289 | C18: =IF(B30>0,B18/B30,0) -> 0.29920133 | D18: =IF(Assumptions!B9>0,B18/Assumptions!B9,0) -> 2.6251875
A19: Developer Fee (5% of Hard+Soft) | B19: =Assumptions!B61*(B13+B17) -> 1249585 | C19: =IF(B30>0,B19/B30,0) -> 0.03283288 | D19: =IF(Assumptions!B9>0,B19/Assumptions!B9,0) -> 0.28807515
A20: FINANCE COSTS
A21: Loan Broker Fee | B21: =Assumptions!B49 -> 6700 | C21: =IF(B30>0,B21/B30,0) -> 0.00017604268 | D21: =IF(Assumptions!B9>0,B21/Assumptions!B9,0) -> 0.0015445956
A22: Lender Fee | B22: =Assumptions!B50 -> 6700 | C22: =IF(B30>0,B22/B30,0) -> 0.00017604268 | D22: =IF(Assumptions!B9>0,B22/Assumptions!B9,0) -> 0.0015445956
A23: MUD Operation | B23: =Assumptions!B44 -> 240000 | C23: =IF(B30>0,B23/B30,0) -> 0.0063060065 | D23: =IF(Assumptions!B9>0,B23/Assumptions!B9,0) -> 0.055328797
A24: Third Party / Legal | B24: =Assumptions!B45 -> 150000 | C24: =IF(B30>0,B24/B30,0) -> 0.0039412541 | D24: =IF(Assumptions!B9>0,B24/Assumptions!B9,0) -> 0.034580498
A25: Title / Closing | B25: =Assumptions!B51 -> 1178 | C25: =IF(B30>0,B25/B30,0) -> 3.0951982e-05 | D25: =IF(Assumptions!B9>0,B25/Assumptions!B9,0) -> 0.00027157218
A26: Loan Interest | B26: =Assumptions!B53 -> 25800 | C26: =IF(B30>0,B26/B30,0) -> 0.0006778957 | D26: =IF(Assumptions!B9>0,B26/Assumptions!B9,0) -> 0.0059478457
A27: Total Finance Costs | B27: =SUM(B21:B26) -> 430378 | C27: =IF(B30>0,B27/B30,0) -> 0.011308194 | D27: =IF(Assumptions!B9>0,B27/Assumptions!B9,0) -> 0.099217904
A28: Sales Commission (4% gross lot value) | B28: =Assumptions!B60*Assumptions!E17 -> 1575617.5 | C28: =IF(B30>0,B28/B30,0) -> 0.041399392 | D28: =IF(Assumptions!B9>0,B28/Assumptions!B9,0) -> 0.36323758
A30: TOTAL PROJECT COST (USES) | B30: =B13+B17+B18+B19+B27 -> 38058952 | C30: =IF(B30>0,B30/B30,0) -> 1 | D30: =IF(Assumptions!B9>0,B30/Assumptions!B9,0) -> 8.7739835

Sheet Capital Stack
A1: INTERNATIONAL TRADE PARK HOUSTON — CAPITAL STACK
A2: MUD Bond Structure | Construction Loan | Equity
A4: MUD BOND STRUCTURE
A5: Parameter | B5: Amount / Value | C5: Note
A6: MUD Bond Principal — Total | B6: =Assumptions!B43 -> 23400000 | C6: Two issuances
A7: First Issuance (Month 15) | B7: =Assumptions!B43*0.5 -> 11700000 | C7: Nov 2027
A8: Second Issuance (Month 21) | B8: =Assumptions!B43*0.5 -> 11700000 | C8: May 2028
A9: MUD Operation Cost | B9: =Assumptions!B44 -> 240000 | C9: Annual ops reserve
A10: Third Party / Legal | B10: =Assumptions!B45 -> 150000 | C10: Bond counsel & filing
A12: CONSTRUCTION LOAN
A13: Peak Loan Balance | B13: =Assumptions!B52 -> 671535
A14: Interest Rate (Annual) | B14: =Assumptions!B48 -> 0.11
A15: Broker Fee | B15: =Assumptions!B49 -> 6700
A16: Lender Fee | B16: =Assumptions!B50 -> 6700
A17: Loan Interest Paid | B17: =Assumptions!B53 -> 25800
A18: Title / Closing | B18: =Assumptions!B51 -> 1178
A20: EQUITY CONTRIBUTION
A21: Deemed Land Value (EP Contribution) | B21: =Assumptions!B56 -> 11387289
A22: Developer Cash Equity | B22: 0
A23: Total Equity | B23: =Assumptions!B56 -> 11387289
A25: CAPITAL STACK SUMMARY
A26: Tranche | B26: Amount | C26: % of Total Cost | D26: Cost of Capital
A27: MUD Bond Proceeds | B27: =Assumptions!B43 -> 23400000 | C27: =B27/SUM(B27:B29) -> 0.65992036 | D27: 0
A28: Construction Loan | B28: =Assumptions!B52 -> 671535 | C28: =B28/SUM(B27:B29) -> 0.018938445 | D28: =Assumptions!B48 -> 0.11
A29: Equity (Deemed Land) | B29: =Assumptions!B56 -> 11387289 | C29: =B29/SUM(B27:B29) -> 0.32114119 | D29: =Assumptions!B57 -> 0.08
A30: TOTAL CAPITAL | B30: =SUM(B27:B29) -> 35458824 | C30: =1 -> 1
A32: UNDERWRITING TESTS
A33: Gross Lot Value | B33: =Assumptions!E17 -> 39390437
A34: Net Lot Value (after 4% commission) | B34: =Assumptions!E17*(1-Assumptions!B60) -> 37814820
A35: Total Revenue (Lots + MUD) | B35: =Assumptions!E17*(1-Assumptions!B60)+Assumptions!B56 -> 49202109
A36: Total Project Cost | B36: ='Dev Budget'!B30 -> 38058952
A37: Gross Profit | B37: =Assumptions!E17*(1-Assumptions!B60)+Assumptions!B56-'Dev Budget'!B30 -> 11143157
A38: Project IRR (Est.) | B38: 0.636
A39: Project Multiple (Est.) | B39: 3.03
A40: Equity IRR (Est.) | B40: 0.393
A41: Equity Multiple (Est.) | B41: 2.11

Sheet Pro Forma
A1: INTERNATIONAL TRADE PARK HOUSTON — PRO FORMA
A2: Revenue Summary | Lot Sales by Type | Absorption Schedule
A4: REVENUE SUMMARY
A5: Gross Lot Value | B5: =Assumptions!E17 -> 39390437
A6: Less: Sales Commission (4%) | B6: =-(Assumptions!B60*Assumptions!E17) -> -1575617.5
A7: Net Lot Revenue | B7: =Assumptions!E17*(1-Assumptions!B60) -> 37814820
A8: MUD Bond Proceeds | B8: =Assumptions!B43 -> 23400000
A9: TOTAL REVENUE | B9: =Assumptions!E17*(1-Assumptions!B60)+Assumptions!B43 -> 61214820
A11: COST SUMMARY
A12: Total Hard Costs | B12: ='Dev Budget'!B13 -> 23588700
A13: Total Soft Costs | B13: ='Dev Budget'!B17 -> 1403000
A14: Deemed Land Value | B14: =Assumptions!B56 -> 11387289
A15: Developer Fee | B15: ='Dev Budget'!B19 -> 1249585
A16: Total Finance Costs | B16: ='Dev Budget'!B27 -> 430378
A17: Sales Commission | B17: ='Dev Budget'!B28 -> 1575617.5
A18: TOTAL PROJECT COST | B18: ='Dev Budget'!B30 -> 38058952
A20: PROFIT SUMMARY
A21: TOTAL PROFIT | B21: =Assumptions!E17*(1-Assumptions!B60)+Assumptions!B43-'Dev Budget'!B30 -> 23155868
A22: Developer Net Profit | B22: =('Pro Forma'!B21)*Assumptions!B58 -> 11577934
A23: Equity Partner Net Profit | B23: =('Pro Forma'!B21)*Assumptions!B59 -> 11577934
A25: LOT SALES BY TYPE
A26: Lot Type | B26: # Lots | C26: Total Acres | D26: Net SF | E26: Price/SF | F26: Gross Value | G26: % Revenue
A27: Industrial | B27: =Assumptions!B14 -> 8 | C27: =Assumptions!C14 -> 27.6 | D27: =Assumptions!C14*43560 -> 1202256 | E27: =Assumptions!D14 -> 7.653 | F27: =Assumptions!E14 -> 9190000 | G27: =F27/F30 -> 0.23330536
A28: Retail | B28: =Assumptions!B15 -> 18 | C28: =Assumptions!C15 -> 23.5 | D28: =Assumptions!C15*43560 -> 1023660 | E28: =Assumptions!D15 -> 14.556 | F28: =Assumptions!E15 -> 14900000 | G28: =F28/F30 -> 0.3782644
A29: Multifamily | B29: =Assumptions!B16 -> 4 | C29: =Assumptions!C16 -> 48.5 | D29: =Assumptions!C16*43560 -> 2112660 | E29: =Assumptions!D16 -> 7.242 | F29: =Assumptions!E16 -> 15300437 | G29: =F29/F30 -> 0.38843024
A30: TOTAL | B30: =SUM(B27:B29) -> 30 | C30: =SUM(C27:C29) -> 99.6 | D30: =SUM(D27:D29) -> 4338576 | F30: =SUM(F27:F29) -> 39390437 | G30: =1 -> 1
A32: ABSORPTION SCHEDULE
A33: Lot sales months 5-22 from project start (Feb 2026)
A34: Lot Type | B34: Lots/Month | C34: Sales Start | D34: Sales End | E34: Total Lots | F34: Total Revenue
A35: Industrial | B35: =Assumptions!B14/(Assumptions!B24-Assumptions!B23+1) -> 0.44444444 | C35: =Assumptions!B23 -> 5 | D35: =Assumptions!B24 -> 22
A36: Retail | B36: =Assumptions!B15/(Assumptions!B24-Assumptions!B23+1) -> 1 | C36: =Assumptions!B23 -> 5 | D36: =Assumptions!B24 -> 22
A37: Multifamily | B37: =Assumptions!B16/(Assumptions!B24-Assumptions!B23+1) -> 0.22222222 | C37: =Assumptions!B23 -> 5 | D37: =Assumptions!B24 -> 22

Sheet JV Waterfall
A1: INTERNATIONAL TRADE PARK HOUSTON — JV WATERFALL
A2: 8% Preferred Return + 50/50 Profit Split
A4: EQUITY STRUCTURE
B5: Equity Partner | C5: Developer | D5: Total
A6: Initial Contribution (Deemed Land) | B6: =Assumptions!B56 -> 11387289 | C6: 0 | D6: =B6+C6 -> 11387289
A8: DISTRIBUTION WATERFALL
A9: Step 1: Return of Capital (EP) | B9: =Assumptions!B56 -> 11387289 | C9: =0 -> 0
A10: Step 2: 8% Preferred Return (EP) | B10: =Assumptions!B56*Assumptions!B57 -> 910983.12 | C10: =0 -> 0 | E10: 8% p.a. on $11.4M
A11: Step 3: Return of Dev Capital | B11: =0 -> 0 | C11: ='Dev Budget'!B19 -> 1249585
A12: Step 4: 50/50 Profit Split | E12: Residual distributable profit
A13: Distributable Profit | B13: =(Assumptions!E17*(1-Assumptions!B60)+Assumptions!B43-'Dev Budget'!B30)-Assumptions!B56-Assumptions!B56*Assumptions!B57 -> 10857595
A14: 50% to Equity Partner | B14: =B13*Assumptions!B59 -> 5428797.7
A15: 50% to Developer | C15: =B13*Assumptions!B58 -> 5428797.7
A17: RETURNS SUMMARY
B18: Equity Partner | C18: Developer | D18: Total
A19: Total Distributions | B19: =Assumptions!B56+Assumptions!B56*Assumptions!B57+B12*Assumptions!B59 -> 12298272 | C19: ='Dev Budget'!B19+B13*Assumptions!B58 -> 6678382.7 | D19: =B19+C19 -> 18976655
A20: Net Profit | B20: =B19-Assumptions!B56 -> 910983.12 | C20: =C19 -> 6678382.7 | D20: =B20+C20 -> 7589365.8
A21: IRR (Est.) | B21: 0.393 | C21: 0.636
A22: Multiple (Est.) | B22: 2.11 | C22: 3.03

Sheet Cap Events
A1: INTERNATIONAL TRADE PARK HOUSTON — CAPITAL EVENTS
A2: Scenario A: JV Partner Buyout | Scenario B: Full Development
A4: SCENARIO A: JV PARTNER BUYOUT | E4: SCENARIO B: FULL DEVELOPMENT
A5: Item | B5: Amount | C5: Note | E5: Item | F5: Amount | G5: Note
A6: Buyout Date (Month) | B6: 18 | C6: Approx. mid-project | E6: Project Duration (Months) | F6: =Assumptions!B22 -> 50 | G6: 50 months
A7: EP Contribution Returned | B7: =Assumptions!B56 -> 11387289 | C7: Return of deemed land | E7: Total Revenue | F7: =Assumptions!E17*(1-Assumptions!B60)+Assumptions!B43 -> 61214820 | G7: Lots + MUD
A8: Preferred Return Accrued | B8: =Assumptions!B56*Assumptions!B57*(18/12) -> 1366474.7 | C8: 8% for 18 months | E8: Total Project Cost | F8: ='Dev Budget'!B30 -> 38058952 | G8: All-in cost
A9: Total Buyout Price | B9: =Assumptions!B56+Assumptions!B56*Assumptions!B57*(18/12) -> 12753764 | E9: Total Profit | F9: =F7-F8 -> 23155868
A10: Developer Net Position | B10: =Assumptions!E16*(1-Assumptions!B60)+Assumptions!B56-'Dev Budget'!B30-B9 -> -24737007 | C10: Post-buyout dev profit | E10: Developer Share (50%) | F10: =F9*Assumptions!B58 -> 11577934
E11: EP Share (50%) | F11: =F9*Assumptions!B59 -> 11577934

Sheet Balance Sheet
A1: INTERNATIONAL TRADE PARK HOUSTON — BALANCE SHEET
A2: Day 1 | 50% Sold | Full Sellout
A4: EQUITY POSITION
B5: Day 1 | C5: 50% Sold | D5: Full Sellout
A6: ASSETS
A7: Land (Deemed Value) | B7: =Assumptions!B56 -> 11387289 | C7: =Assumptions!B56 -> 11387289 | D7: =0 -> 0
A8: Development in Progress | B8: =0 -> 0 | C8: ='Dev Budget'!B13*0.5 -> 11794350 | D8: =0 -> 0
A9: Cash / MUD Proceeds Received | B9: =0 -> 0 | C9: =Assumptions!B43*0.5 -> 11700000 | D9: =Assumptions!B43 -> 23400000
A10: Lot Receivables | B10: =0 -> 0 | C10: =Assumptions!E16*0.5 -> 7650218.5 | D10: =0 -> 0
A11: TOTAL ASSETS | B11: =SUM(B7:B10) -> 11387289 | C11: =SUM(C7:C10) -> 42531858 | D11: =SUM(D7:D10) -> 23400000
A13: LIABILITIES
A14: Construction Loan | B14: =0 -> 0 | C14: =Assumptions!B52*0.5 -> 335767.5 | D14: =0 -> 0
A15: Accrued Preferred Return | B15: =0 -> 0 | C15: =Assumptions!B56*Assumptions!B57*(Assumptions!B24*0.5/12) -> 835067.86 | D15: =Assumptions!B56*Assumptions!B57*(Assumptions!B24/12) -> 1670135.7
A16: TOTAL LIABILITIES | B16: =B14+B13 -> 0 | C16: =C14+C13 -> 335767.5 | D16: =D14+D13 -> 0
A18: EQUITY
A19: Equity Partner | B19: =Assumptions!B56 -> 11387289
A20: Developer | B20: =0 -> 0
A21: Retained Earnings | B21: =0 -> 0
A22: TOTAL EQUITY | B22: =B20+B19 -> 11387289 | C22: =C20+C19 -> 0 | D22: =D20+D19 -> 0

Sheet P&L
A1: INTERNATIONAL TRADE PARK HOUSTON — P&L STATEMENT
A2: Full Project Profit & Loss
A4: REVENUE
A5: Gross Lot Sales | B5: =Assumptions!E17 -> 39390437
A6: Less: Sales Commission | B6: =-(Assumptions!B60*Assumptions!E17) -> -1575617.5
A7: Net Lot Revenue | B7: =Assumptions!E17*(1-Assumptions!B60) -> 37814820
A8: MUD Bond Proceeds | B8: =Assumptions!B43 -> 23400000
A9: TOTAL REVENUE | B9: =Assumptions!E17*(1-Assumptions!B60)+Assumptions!B43 -> 61214820
A11: COST OF SALES (HARD COSTS)
A12: Water System | B12: =Assumptions!B29 -> 1993000
A13: Sanitary Sewer | B13: =Assumptions!B30 -> 3432000
A14: Storm Sewer | B14: =Assumptions!B31 -> 12527000
A15: Roadway | B15: =Assumptions!B32 -> 5098000
A16: Erosion Control | B16: =Assumptions!B33 -> 262000
A17: Contingency | B17: =Assumptions!B34 -> 276700
A18: TOTAL COST OF SALES (HARD COSTS) | B18: =Assumptions!B35 -> 23588700
A20: SOFT COSTS
A21: Testing / Inspection | B21: =Assumptions!B38 -> 1320000
A22: Engineering & Survey | B22: =Assumptions!B39 -> 83000
A23: TOTAL SOFT COSTS | B23: =Assumptions!B40 -> 1403000
A25: OTHER PROJECT COSTS
A26: Deemed Land Value | B26: =Assumptions!B56 -> 11387289
A27: Developer Fee | B27: ='Dev Budget'!B19 -> 1249585
A28: Finance Costs | B28: ='Dev Budget'!B27 -> 430378
A29: TOTAL OTHER PROJECT COSTS | B29: =Assumptions!B56+'Dev Budget'!B19+'Dev Budget'!B27 -> 13067252
A31: GROSS PROFIT (EBITDA) | B31: =B9-B18-B23 -> 36223120
A33: FINANCE COSTS (Below EBITDA)
A34: Loan Interest | B34: =Assumptions!B53 -> 25800
A35: Broker Fee | B35: =Assumptions!B49 -> 6700
A36: Lender Fee | B36: =Assumptions!B50 -> 6700
A37: MUD Operation | B37: =Assumptions!B44 -> 240000
A38: Third Party / Legal | B38: =Assumptions!B45 -> 150000
A39: Title / Closing | B39: =Assumptions!B51 -> 1178
A40: TOTAL FINANCE COSTS | B40: ='Dev Budget'!B27 -> 430378
