Workbook

Sheet Cover
B2: THE PLAZA AT WATSONVILLE
B3: Keystone Private Equity Request — Capital Model
B4: 140 UNITS | 4% LIHTC | TAX-EXEMPT BONDS | SECTION 8 HCV | RETAIL PAVILION
B6: $69,733,653 | D6: 140 | F6: 1.15x
B7: Total Dev Cost | D7: Total Units | F7: Permanent DSCR
B9: MODEL NAVIGATION
B10: Assumptions | C10: All hardcoded inputs — rates, costs, rents, timing
B11: Dev Budget | C11: Sources & Uses · Full development cost by line item
B12: Capital Stack | C12: LIHTC structure · Bond test · Construction financing
B13: Pro Forma | C13: Unit mix · Revenue · NOI · Stabilized value
B14: JV Waterfall | C14: Land equity · Preferred return · 50/50 profit split
B15: Cap Events | C15: Refi Year 3 · Sale Year 10 · JV partner returns
B16: Balance Sheet | C16: Day 1 · Year 15 LIHTC exit · Net equity positions
B17: Sensitivity | C17: NOI / Cap rate / Construction cost stress matrix
B20: PLUSAdvantage™ 2026 · Western Realty Finance · April 12, 2026 · CONFIDENTIAL
B22: COLOR CODING LEGEND
B23: ● | C23: Blue text = Hardcoded input — change to model scenarios
B24: ● | C24: Green text = Formula linked from another sheet
B25: ● | C25: Black text = Calculated formula within this sheet
B26: ● | C26: Yellow fill = Key assumption — review before use

Sheet Assumptions
B1: ASSUMPTIONS — HARDCODED INPUTS (Blue = Change to Model Scenarios)
B3: PROJECT BASICS
B4: Total Units | C4: 140 | D4: Source: KPER v12
B5: New Construction Units | C5: 100
B6: Air-Rights Units | C6: 40 | D6: 28 2nd St
B7: Retail SF (335 Main) | C7: 2000 | D7: Pavilion only
B8: Target AMI Level | C8: 60% AMI
B9: Construction Start | C9: Q3 2026 | D9: Estimated
B10: Construction Term (mo) | C10: 36
B11: Stabilization Month | C11: 42
B13: LAND & ACQUISITION
B14: 335 Main St — Est. MV | C14: 1200000 | D14: Romo family; no debt
B15: 28 2nd St — Est. MV | C15: 3796214 | D15: Romo family
B16: 28 2nd St — Existing Debt | C16: 2420000 | D16: Heritage Bank (current)
B17: 210 Rodriguez — City | C17: 114780 | D17: Pending confirmation
B18: 320 Rodriguez — City | C18: 114780 | D18: Pending confirmation
B20: CONSTRUCTION COSTS
B21: New Construction ($/unit) | C21: 310000 | D21: 100 units
B22: Air-Rights ($/unit) | C22: 270000 | D22: 40 units
B23: Retail Pavilion | C23: 1500000 | D23: 335 Main St
B24: Horizontal Hard Costs | C24: 3450000 | D24: Site, utilities, demo
B25: Contingency % | C25: 0.05 | D25: 5% of hard costs
B26: Developer Fee % | C26: 0.07 | D26: 7% of TDC
B28: FINANCING — CONSTRUCTION
B29: Bond Rate (Tax-Exempt IO) | C29: 0.055 | D29: 5.5%
B30: Construction Term (mo) | C30: 36
B31: Interest Reserve Factor | C31: 0.5 | D31: 50% of full-term interest
B32: Lender Fee % | C32: 0.015 | D32: 1.5%
B33: Broker Fee % | C33: 0.01 | D33: 1.0%
B34: Closing Costs | C34: 75000 | D34: Fixed
B35: LTC Ceiling | C35: 0.8 | D35: 80% — policy max
B36: LTV Ceiling | C36: 0.65 | D36: 65% — governs
B38: FINANCING — PERMANENT
B39: Permanent Loan Rate | C39: 0.045 | D39: 4.5% fixed
B40: Permanent Term (yr) | C40: 35 | D40: Agency forward
B41: Permanent Amortization | C41: 35 | D41: Years
B42: Target DSCR | C42: 1.15
B44: LIHTC / TAX CREDITS
B45: Eligible Basis | C45: 55303745
B46: High-Cost Area Boost | C46: 1.3 | D46: 130% — Watsonville
...

Sheet Dev Budget
B1: DEVELOPMENT BUDGET — SOURCES & USES
B2: Line Item | C2: Amount | D2: % Total | E2: Per Unit | F2: Notes
B3: USES OF FUNDS
B4: Land & Acquisition | C4: 5213360 | E4: =IFERROR(C4/140,"") -> 37238.286 | F4: Four parcels incl. city contribution
B5: 335 Main St (JV Partner) | C5: 1200000 | E5: =IFERROR(C5/140,"") -> 8571.4286 | F5: Est. MV, no debt
B6: 28 2nd St (net of debt) | C6: 1376214 | E6: =IFERROR(C6/140,"") -> 9830.1 | F6: MV $3.8M less $2.42M Heritage
B7: 210 Rodriguez (City) | C7: 114780 | E7: =IFERROR(C7/140,"") -> 819.85714 | F7: Pending confirmation
B8: 320 Rodriguez (City) | C8: 114780 | E8: =IFERROR(C8/140,"") -> 819.85714 | F8: Pending confirmation
B9: Other Acquisition | C9: 2407586 | E9: =IFERROR(C9/140,"") -> 17197.043 | F9: Title, closing, misc
B10: Horizontal Hard Costs | C10: 3450000 | E10: =IFERROR(C10/140,"") -> 24642.857 | F10: Site, utilities, demo $800K
B11: New Construction (100×$310K) | C11: 31000000 | E11: =IFERROR(C11/140,"") -> 221428.57 | F11: 100 units new construction
B12: Air-Rights (40×$270K) | C12: 10800000 | E12: =IFERROR(C12/140,"") -> 77142.857 | F12: 40 units — 28 2nd St
B13: Retail Pavilion (335 Main) | C13: 1500000 | E13: =IFERROR(C13/140,"") -> 10714.286 | F13: Pavilion, ground floor
B14: Contingency (5%) | C14: 2739636 | E14: =IFERROR(C14/140,"") -> 19568.829
B15: Soft Costs & Fees | C15: 8042719 | E15: =IFERROR(C15/140,"") -> 57447.993 | F15: Arch, eng, legal, permits
B16: Developer Fee (7%) | C16: 3961026 | E16: =IFERROR(C16/140,"") -> 28293.043 | F16: 50/50 split w/ NP GP
B17: Financing Costs & Reserves | C17: 5446912 | E17: =IFERROR(C17/140,"") -> 38906.514 | F17: Interest reserve, fees, closing
B18: TOTAL PROJECT COST | C18: 69733653 | D18: 1 | E18: =IFERROR(C18/140,"") -> 498097.52
B20: SOURCES OF FUNDS
B21: Source | C21: Amount | D21: % TDC | E21: Notes
B22: Senior Construction Loan | C22: 40470568 | D22: 58.0% | E22: LTV governs — 61.4%
B23: LIHTC Tax Credit Equity (4%) | C23: 26457311 | D23: 37.9% | E23: Subordinate gap capital
B24: JV Land — 335 Main St | C24: 1200000 | D24: 1.7% | E24: Romo; no debt
B25: JV Land — 28 2nd St (net) | C25: 1376214 | D25: 2.0% | E25: Net of $2.42M Heritage debt
B26: City Land Contribution | C26: 229560 | D26: 0.3% | E26: 210 + 320 Rodriguez
B27: TOTAL SOURCES | C27: =SUM(C22:C26) -> 69733653

Sheet Capital Stack
B1: CAPITAL STACK — LIHTC FINANCING STRUCTURE
B2: PHASE 1: CONSTRUCTION FINANCING
B3: Senior Loan Amount | C3: ='Dev Budget'!C22 -> 40470568 | D3: LTV governs
B4: Bond Rate (Tax-Exempt IO) | C4: =Assumptions!C30 -> 36
B5: Construction Term (months) | C5: =Assumptions!C31 -> 0.5
B6: Monthly Debt Service (IO) | C6: ='Dev Budget'!C22*Assumptions!C30/12 -> 121411704 | D6: Interest only
B7: Annual Interest (full term) | C7: ='Dev Budget'!C22*Assumptions!C30 -> 1456940448
B8: Interest Reserve (50%) | C8: ='Dev Budget'!C22*Assumptions!C30*(Assumptions!C31/12)*Assumptions!C32 -> 910587.78
B9: Lender Fee (1.5%) | C9: ='Dev Budget'!C22*Assumptions!C33 -> 404705.68
B10: Broker Fee (1.0%) | C10: ='Dev Budget'!C22*Assumptions!C34 -> 3035292600000
B11: Closing Costs | C11: =Assumptions!C35 -> 0.8 | D11: Fixed
B13: SENIOR LOAN UNDERWRITING TESTS
B14: 80% LTC Ceiling | C14: ='Dev Budget'!C22*Assumptions!C36 -> 26305869 | D14: PASS | E14: CEILING
B15: 65% LTV Ceiling | C15: ='Pro Forma'!C30*Assumptions!C37 -> 0 | D15: PASS | E15: CEILING — GOVERNS
B16: Actual Senior Loan | C16: ='Dev Budget'!C22 -> 40470568 | D16: PASS
B17: LTC (Actual) | C17: ='Dev Budget'!C22/'Dev Budget'!C22 -> 1 | D17: PASS
B18: LTV (Actual) | C18: =IFERROR(C3/'Dev Budget'!C19,0) -> 0 | D18: PASS
B20: LIHTC EQUITY CALCULATION (4%)
B21: Eligible Basis | C21: =Assumptions!C43 -> 0
B22: High-Cost Area Boost (130%) | C22: =Assumptions!C43*Assumptions!C44 -> 0
B23: Boosted Eligible Basis | C23: =Assumptions!C43*Assumptions!C44 -> 0
B24: 4% Annual Credit | C24: =Assumptions!C43*Assumptions!C44*Assumptions!C45 -> 0
B25: Credit Period | C25: =Assumptions!C46 -> 1.3
B26: Total 10-Year Credits | C26: =Assumptions!C43*Assumptions!C44*Assumptions!C45*Assumptions!C46 -> 0
B27: Credit Price | C27: =Assumptions!C47 -> 0.04
B28: TOTAL LIHTC EQUITY | C28: =Assumptions!C43*Assumptions!C44*Assumptions!C45*Assumptions!C46*Assumptions!C47 -> 0
B30: PHASE 2: PERMANENT FINANCING
B31: Permanent Loan Amount | C31: 54119038
B32: Permanent Rate | C32: =Assumptions!C38 -> 0
B33: Term (years) | C33: =Assumptions!C39 -> 0.045
B34: Monthly Payment | C34: =-PMT(Assumptions!C38/12,Assumptions!C39*12,54119038) -> 1.0022044e+08
B35: Annual Debt Service | C35: =(-PMT(Assumptions!C38/12,Assumptions!C39*12,54119038))*12 -> 1.2026453e+09
B36: Stabilized NOI | C36: ='Pro Forma'!C27 -> 0
B37: Permanent DSCR | C37: ='Pro Forma'!C27/((-PMT(Assumptions!C38/12,Assumptions!C39*12,54119038))*12) -> 0

Sheet Pro Forma
B1: REVENUE & STABILIZED PRO FORMA
B2: UNIT MIX & RENT SCHEDULE
B3: Type | C3: Count | D3: SF | E3: Rent/mo | F3: Annual | G3: % Rev
B4: Studio | C4: 15 | D4: 450 | E4: =Assumptions!C50 -> 0 | F4: =D5*E5*12 -> 0 | G4: =IFERROR(F4/F9,"")
B5: 1-BR | C5: 50 | D5: 650 | E5: =Assumptions!C51 -> 0 | F5: =D6*E6*12 -> 19440000 | G5: =IFERROR(F5/F9,"")
B6: 2-BR | C6: 55 | D6: 900 | E6: =Assumptions!C52 -> 1800 | F6: =D7*E7*12 -> 30360000 | G6: =IFERROR(F6/F9,"")
B7: 3-BR | C7: 20 | D7: 1150 | E7: =Assumptions!C53 -> 2200 | F7: =D8*E8*12 -> 0 | G7: =IFERROR(F7/F9,"")
B8: Total | C8: =SUM(C4:C7) -> 140 | F8: =SUM(F4:F7) -> 49800000
B10: STABILIZED PRO FORMA (ANNUAL)
B11: Gross Residential Rent | C11: =F9 -> 0
B12: Less: Vacancy (5%) | C12: =-F9*Assumptions!C54 -> 0
B13: Retail Income | C13: =Assumptions!C55 -> 3400
B14: Effective Gross Income (EGI) | C14: =IFERROR(C21+C22+C23,0) -> 0
B15: Less: Operating Expenses (35%) | C15: =-C24*Assumptions!C56 -> 0
B16: NET OPERATING INCOME | C16: =C24+C25 -> 0
B17: Stabilized Value (4.25% cap) | C17: =C26/Assumptions!C58 -> 0
B18: Less: Permanent Loan | C18: -54119038
B19: Net Equity (Day 1) | C19: =C27+C28 -> 0
B20: Permanent Annual DS | C20: =(-PMT(Assumptions!C38/12,Assumptions!C39*12,54119038))*12 -> 1.2026453e+09
B21: Permanent DSCR | C21: =IFERROR(C26/C30,0) -> 0
B23: Note: In 4% LIHTC projects, stabilized value may be less than TDC — economics driven by tax credits, long-term cash flow, and residual asset value.

Sheet JV Waterfall
B1: JV WATERFALL — PARTNER RETURNS
B2: JV LAND EQUITY CONTRIBUTION — NET OF DEBT
B3: Parcel | C3: Est. MV | D3: Debt | E3: Net Equity
B4: 335 Main St | C4: 1200000 | D4: 0 | E4: =C4-D4 -> 1200000
B5: 28 2nd St | C5: 3796214 | D5: 2420000 | E5: =C5-D5 -> 1376214
B6: TOTAL | C6: =SUM(C4:C5) -> 4996214 | D6: =SUM(D4:D5) -> 2420000 | E6: =SUM(E4:E5) -> 2576214
B8: JV TERMS & DISTRIBUTION WATERFALL
B9: Preferred Return Rate | C9: =Assumptions!C61 -> 0.0425 | D9: Annual, cumulative
B10: Annual Preferred ($) | C10: =E6*Assumptions!C61 -> 109489.1 | D10: JV Partner only
B11: JV Partner Profit Split | C11: =Assumptions!C62 -> 0.045 | D11: 50%
B12: Managing Member Split | C12: =1-Assumptions!C62 -> 0.955 | D12: 50%
B13: Developer Fee | C13: 3961026 | D13: 7% of TDC — 50/50 w/ NP GP
B14: Managing Member Cash Equity | C14: 0 | D14: $0 — LIHTC structure
B16: DISTRIBUTION PRIORITY
B17: Step 01: Return of Land Capital | C17: $2,576,214 — JV Partner first
B18: Step 02: Preferred Return (8%) | C18: $206,097/yr — JV Partner, cumulative
B19: Step 03: Preferred Catch-Up | C19: Any accrued unpaid preferred — JV Partner
B20: Step 04: Residual Profit Split | C20: 50% JV Partner / 50% Managing Member

Sheet Cap Events
B1: CAPITAL EVENT SCENARIOS — JV PARTNER RETURNS
B2: All scenarios assume 2.5% annual NOI/value growth from stabilization.
B3: SCENARIO A: REFINANCE AT YEAR 3
B4: NOI at Year 3 (2.5% growth) | C4: =IFERROR('Pro Forma'!C26*(1+Assumptions!C59)^3,0) -> 0
B5: Project Value (Year 3) | C5: =IFERROR('Pro Forma'!C26*(1+Assumptions!C59)^3/Assumptions!C58,0) -> 0
B6: Refi Loan (80% LTV) | C6: =IFERROR('Pro Forma'!C26*(1+Assumptions!C59)^3/Assumptions!C58*Assumptions!C63,0) -> 0
B7: Less: Payoff Permanent | C7: -54119038
B8: Cash-Out Proceeds | C8: =IFERROR(C5+C6+C7,0) -> -54119038
B9: JV Partner: Return of Capital | C9: =IFERROR(E6,0) -> 0
B10: JV Partner: Accrued Pref (3yr) | C10: =IFERROR(E6*Assumptions!C61*3,0) -> 0
B11: JV Partner: 50% of Residual | C11: =IFERROR((C8-E6-E6*Assumptions!C61*3)*Assumptions!C62,0) -> -2435356.7
B12: JV PARTNER TOTAL (YEAR 3) | C12: =IFERROR(C9+C10+C11,0) -> -2435356.7
B14: SCENARIO B: SALE AT YEAR 10
B15: NOI at Year 10 (2.5% growth) | C15: =IFERROR('Pro Forma'!C26*(1+Assumptions!C59)^10,0) -> 0
B16: Sale Price (4.5% exit cap) | C16: =IFERROR('Pro Forma'!C26*(1+Assumptions!C59)^10/Assumptions!C59,0) -> 0
B17: Less: Disposition Costs (3%) | C17: =IFERROR(-('Pro Forma'!C26*(1+Assumptions!C59)^10/Assumptions!C59)*Assumptions!C63,0) -> 0
B18: Less: Loan Payoff | C18: -54119038
B19: Net Sale Proceeds | C19: =IFERROR(SUM(C15:C18),0) -> -54119038
B20: JV Partner: Return of Capital | C20: =IFERROR(E6,0) -> 0
B21: JV Partner: 50% of Residual | C21: =IFERROR((C19-E6)*Assumptions!C62,0) -> -2435356.7
B22: JV Partner: Cumul CF (10yr) | C22: =IFERROR(E7*10,0) -> 0
B23: JV PARTNER TOTAL RETURN | C23: =IFERROR(SUM(C20:C22),0) -> -2435356.7
B24: JV Partner Equity Multiple | C24: =IFERROR(C23/E6,0) -> 0

Sheet Balance Sheet
B1: STABILIZED BALANCE SHEET — JV EQUITY POSITIONS
B2: Line Item | C2: Day 1 Stabilized | D2: Year 15 (LIHTC Exit) | E2: Notes
B3: Project Value | C3: ='Pro Forma'!C27 -> 0 | D3: ='Pro Forma'!C27*(1+Assumptions!C59)^15 -> 0 | E3: 2.5% annual growth
B4: Less: Permanent Loan | C4: -54119038 | D4: -54119038 | E4: Fixed — agency forward
B5: Net Equity | C5: =C3+C4 -> -54119038 | D5: =D3+D4 -> -54119038 | E5: Project value less debt
B6: JV Partner Share (50%) | C6: =C5*Assumptions!C62 -> -2435356.7 | D6: =D5*Assumptions!C62 -> -2435356.7
B7: Managing Member Share (50%) | C7: =C5*(1-Assumptions!C62) -> -51683681 | D7: =D5*(1-Assumptions!C62) -> -51683681
B9: KEY BALANCE SHEET KPIs
B10: Net Equity — Day 1 | C10: =C5 -> -54119038
B11: JV Partner Share — Day 1 | C11: =C6 -> -2435356.7 | D11: 50% of day 1 equity
B12: Net Equity — Year 15 | C12: =D5 -> -54119038 | D12: GP owns asset at LIHTC exit
B13: JV Partner Share — Year 15 | C13: =D6 -> -2435356.7 | D13: 6.2x from land contribution

Sheet Sensitivity
B1: SENSITIVITY ANALYSIS — STRESS TESTING
B2: Key metrics under different NOI, cap rate, and construction cost scenarios. Change blue cells in Assumptions tab to update.
B3: TABLE 1: STABILIZED VALUE — NOI vs. CAP RATE
B4: NOI \ Cap Rate → | C4: 0.0375 | D4: 0.04 | E4: 0.0425 | F4: 0.045 | G4: 0.0475 | H4: 0.05
B5: 2400000 | C5: 64000000 | D5: 60000000 | E5: 56470588 | F5: 53333333 | G5: 50526316 | H5: 48000000
B6: 2600000 | C6: 69333333 | D6: 65000000 | E6: 61176471 | F6: 57777778 | G6: 54736842 | H6: 52000000
B7: 2800660 | C7: 74684267 | D7: 70016500 | E7: 65897882 | F7: 62236889 | G7: 58961263 | H7: 56013200
B8: 3000000 | C8: 80000000 | D8: 75000000 | E8: 70588235 | F8: 66666667 | G8: 63157895 | H8: 60000000
B9: 3200000 | C9: 85333333 | D9: 80000000 | E9: 75294118 | F9: 71111111 | G9: 67368421 | H9: 64000000
B10: 3400000 | C10: 90666667 | D10: 85000000 | E10: 80000000 | F10: 75555556 | G10: 71578947 | H10: 68000000
B12: TABLE 2: DSCR — NOI vs. PERMANENT RATE
B13: NOI \ Perm Rate → | C13: 0.035 | D13: 0.04 | E13: 0.045 | F13: 0.05 | G13: 0.055 | H13: 0.06
B14: 2400000 | C14: 0.89417879 | D14: 0.83463596 | E14: 0.78087789 | F14: 0.73224637 | G14: 0.68816483 | H14: 0.64812766
B15: 2600000 | C15: 0.96869369 | D15: 0.90418895 | E15: 0.84595105 | F15: 0.7932669 | G15: 0.7455119 | H15: 0.70213829
B16: 2800660 | C16: 1.0434545 | D16: 0.97397147 | E16: 0.91123895 | F16: 0.8544888 | G16: 0.80304822 | H16: 0.75632717
B17: 3000000 | C17: 1.1177235 | D17: 1.0432949 | E17: 0.97609736 | F17: 0.91530797 | G17: 0.86020604 | H17: 0.81015957
B18: 3200000 | C18: 1.1922384 | D18: 1.1128479 | E18: 1.0411705 | F18: 0.9763285 | G18: 0.91755311 | H18: 0.86417021
B19: 3400000 | C19: 1.2667533 | D19: 1.1824009 | E19: 1.1062437 | F19: 1.037349 | G19: 0.97490018 | H19: 0.91818085
B21: Gold = Base case. Green = Above threshold. Red = Below minimum policy floor.
